Workbook

Sheet 29
A1: MLHUILLIER PHILIPPINES
A2: BILLS PAYMENT REPORT
A3: Report Date : AUGUST 2025
F4: MLKP7 | J4: Cancelled (web) | N4: Net Total Trxns | R4: Billed Amount | V4: Current Variance
A5: No. | B5: Partner's Name | C5: Banks | D5: CHARGING TYPE | F5: Vol | G5: Principal | H5: Charge | J5: Vol | K5: Principal | L5: Charge | N5: Vol | O5: Principal | P5: Charge | R5: Vol | S5: Amount | T5: Charge | V5: Vol | W5: Amount
A6: 1 | B6: 123 LENDING CORPORATION | C6: BDO | D6: Customer | F6: 8 | G6: 109814 | H6: 800 | J6: 0 | K6: 0 | L6: 0 | N6: 8 | O6: 109814 | P6: 800 | R6: 0 | S6: 0 | T6: 0 | V6: 8 | W6: 109814
A7: 2 | B7: A-1 MILLING CORPORATION | C7: METROBANK | D7: Customer | F7: 4 | G7: 651400 | H7: 350 | J7: 0 | K7: 0 | L7: 0 | N7: 4 | O7: 651400 | P7: 350 | R7: 0 | S7: 0 | T7: 0 | V7: 4 | W7: 651400
A8: 3 | B8: A2M GLOBAL DISTRIBUTION INC. | C8: METROBANK | D8: Partner | F8: 6 | G8: 97977.82 | H8: 300 | J8: 0 | K8: 0 | L8: 0 | N8: 6 | O8: 97977.82 | P8: 300 | R8: 0 | S8: 0 | T8: 0 | V8: 6 | W8: 97977.82
A9: 4 | B9: ABEJO WATERS CORP - CEBU | C9: BPI ONLINE | D9: Customer | F9: 0 | G9: 0 | H9: 0 | J9: 0 | K9: 0 | L9: 0 | N9: 0 | O9: 0 | P9: 0 | R9: 0 | S9: 0 | T9: 0 | V9: 0 | W9: 0
A10: 5 | B10: ABEJO WATERS CORP - TALISAY | C10: CHINABANK | D10: Customer | F10: 0 | G10: 0 | H10: 0 | J10: 0 | K10: 0 | L10: 0 | N10: 0 | O10: 0 | P10: 0 | R10: 0 | S10: 0 | T10: 0 | V10: 0 | W10: 0
A11: 6 | B11: AEON CREDIT SERVICE PHIL INC. API | C11: METROBANK | D11: Customer | F11: 7 | G11: 17562.38 | H11: 105 | J11: 0 | K11: 0 | L11: 0 | N11: 7 | O11: 17562.38 | P11: 105 | R11: 0 | S11: 0 | T11: 0 | V11: 7 | W11: 17562.38
A12: 7 | B12: AF PAYMENTS (BEEP LOADING) | C12: BPI CHECK | D12: Customer | F12: 0 | G12: 0 | H12: 0 | J12: 0 | K12: 0 | L12: 0 | N12: 0 | O12: 0 | P12: 0 | R12: 0 | S12: 0 | T12: 0 | V12: 0 | W12: 0
A13: 8 | B13: AIA PHILIPPINES | C13: BPI | D13: Customer | F13: 8 | G13: 79687 | H13: 200 | J13: 0 | K13: 0 | L13: 0 | N13: 8 | O13: 79687 | P13: 200 | R13: 0 | S13: 0 | T13: 0 | V13: 8 | W13: 79687
A14: 9 | B14: AIR ASIA/ZEST AIR | C14: BDO | D14: Partner | F14: 4 | G14: 17588.96 | H14: 80 | J14: 0 | K14: 0 | L14: 0 | N14: 4 | O14: 17588.96 | P14: 80 | R14: 0 | S14: 0 | T14: 0 | V14: 4 | W14: 17588.96
A15: 10 | B15: AIR YOU GO TRAVEL PHILS CO. | C15: BDO | D15: Customer | F15: 0 | G15: 0 | H15: 0 | J15: 0 | K15: 0 | L15: 0 | N15: 0 | O15: 0 | P15: 0 | R15: 0 | S15: 0 | T15: 0 | V15: 0 | W15: 0
A16: 11 | B16: AKLAN CABLE NETWORK, INC. - LEMERY | D16: Customer | F16: 0 | G16: 0 | H16: 0 | J16: 0 | K16: 0 | L16: 0 | N16: 0 | O16: 0 | P16: 0 | R16: 0 | S16: 0 | T16: 0 | V16: 0 | W16: 0
A17: 12 | B17: ALFA- ALL FOOD ASIA, INC. | C17: METROBANK | D17: Customer | F17: 0 | G17: 0 | H17: 0 | J17: 0 | K17: 0 | L17: 0 | N17: 0 | O17: 0 | P17: 0 | R17: 0 | S17: 0 | T17: 0 | V17: 0 | W17: 0
A18: 13 | B18: AMBROSIA PHILS INC | C18: METROBANK | D18: Partner | F18: 56 | G18: 1155780.3 | H18: 1650 | J18: 0 | K18: 0 | L18: 0 | N18: 56 | O18: 1155780.3 | P18: 1650 | R18: 0 | S18: 0 | T18: 0 | V18: 56 | W18: 1155780.3
A19: 14 | B19: ANECO | C19: BPI | D19: Customer | F19: 11 | G19: 36783.03 | H19: 55 | J19: 0 | K19: 0 | L19: 0 | N19: 11 | O19: 36783.03 | P19: 55 | R19: 0 | S19: 0 | T19: 0 | V19: 11 | W19: 36783.03
A20: 15 | B20: ANECO COLLECTIONS | C20: BPI | D20: Customer | F20: 0 | G20: 0 | H20: 0 | J20: 0 | K20: 0 | L20: 0 | N20: 0 | O20: 0 | P20: 0 | R20: 0 | S20: 0 | T20: 0 | V20: 0 | W20: 0
A21: 16 | B21: ANGELES CITY WATER DISTRICT | C21: LANBANK | D21: Customer | F21: 0 | G21: 0 | H21: 0 | J21: 0 | K21: 0 | L21: 0 | N21: 0 | O21: 0 | P21: 0 | R21: 0 | S21: 0 | T21: 0 | V21: 0 | W21: 0
A22: 17 | B22: AQUA CENTRO MWPV CORP. | C22: BPI ONLINE | D22: CusPart | F22: 0 | G22: 0 | H22: 0 | J22: 0 | K22: 0 | L22: 0 | N22: 0 | O22: 0 | P22: 0 | R22: 0 | S22: 0 | T22: 0 | V22: 0 | W22: 0
A23: 18 | B23: ASIALINK FINANCE CORPORATION | C23: BDO | D23: Partner M. | F23: 605 | G23: 12351943 | H23: 10176 | J23: 0 | K23: 0 | L23: 0 | N23: 605 | O23: 12351943 | P23: 10176 | R23: 0 | S23: 0 | T23: 0 | V23: 605 | W23: 12351943
A24: 19 | B24: ASIAN COLLEGE OF SCIENCE AND TECHNOLOGY FDN. INC. | C24: BPI ONLINE | D24: Customer | F24: 0 | G24: 0 | H24: 0 | J24: 0 | K24: 0 | L24: 0 | N24: 0 | O24: 0 | P24: 0 | R24: 0 | S24: 0 | T24: 0 | V24: 0 | W24: 0
A25: 20 | B25: ASIAN COLLEGE OF TECHNOLOGY (ACT) | D25: Customer | F25: 0 | G25: 0 | H25: 0 | J25: 0 | K25: 0 | L25: 0 | N25: 0 | O25: 0 | P25: 0 | R25: 0 | S25: 0 | T25: 0 | V25: 0 | W25: 0
A26: 21 | B26: ASIAN INTERNATIONAL SCHOOL OF AERONAUTICS AND TECHNOLOGY (AISAT) CORP. | C26: METROBANK | D26: Customer | F26: 0 | G26: 0 | H26: 0 | J26: 0 | K26: 0 | L26: 0 | N26: 0 | O26: 0 | P26: 0 | R26: 0 | S26: 0 | T26: 0 | V26: 0 | W26: 0
A27: 22 | B27: ATENEO DE DAVAO UNIVERSITY | C27: PNB | D27: Customer | F27: 0 | G27: 0 | H27: 0 | J27: 0 | K27: 0 | L27: 0 | N27: 0 | O27: 0 | P27: 0 | R27: 0 | S27: 0 | T27: 0 | V27: 0 | W27: 0
A28: 23 | B28: ATENEO DE ZAMBOANGA UNIVERSITY | C28: METROBANK | D28: Customer | F28: 0 | G28: 0 | H28: 0 | J28: 0 | K28: 0 | L28: 0 | N28: 0 | O28: 0 | P28: 0 | R28: 0 | S28: 0 | T28: 0 | V28: 0 | W28: 0
A29: 24 | B29: ATLAS CEBU CORN MILL CORP | C29: CHINABANK | D29: Customer | F29: 6 | G29: 239025 | H29: 300 | J29: 0 | K29: 0 | L29: 0 | N29: 6 | O29: 239025 | P29: 300 | R29: 0 | S29: 0 | T29: 0 | V29: 6 | W29: 239025
A30: 25 | B30: BAKERS BEST MARKETING CORPORATION | C30: BPI | D30: Customer | F30: 3 | G30: 18925 | H30: 90 | J30: 0 | K30: 0 | L30: 0 | N30: 3 | O30: 18925 | P30: 90 | R30: 0 | S30: 0 | T30: 0 | V30: 3 | W30: 18925
A31: 26 | B31: BALAMBAN ENERZONE | D31: No Billers | F31: 0 | G31: 0 | H31: 0 | J31: 0 | K31: 0 | L31: 0 | N31: 0 | O31: 0 | P31: 0 | R31: 0 | S31: 0 | T31: 0 | V31: 0 | W31: 0
A32: 27 | B32: BALAMBAN WATER DISTRICT | C32: LANBANK | D32: Customer | F32: 14 | G32: 8218.85 | H32: 140 | J32: 0 | K32: 0 | L32: 0 | N32: 14 | O32: 8218.85 | P32: 140 | R32: 0 | S32: 0 | T32: 0 | V32: 14 | W32: 8218.85
A33: 28 | B33: BASIC WATER ENTERPRISES INC. | C33: METROBANK | D33: Partner | F33: 0 | G33: 0 | H33: 0 | J33: 0 | K33: 0 | L33: 0 | N33: 0 | O33: 0 | P33: 0 | R33: 0 | S33: 0 | T33: 0 | V33: 0 | W33: 0
A34: 29 | B34: BATANGAS CATV, INC. - BATANGAS | D34: Customer | F34: 0 | G34: 0 | H34: 0 | J34: 0 | K34: 0 | L34: 0 | N34: 0 | O34: 0 | P34: 0 | R34: 0 | S34: 0 | T34: 0 | V34: 0 | W34: 0
A35: 30 | B35: BATANGAS CATV, INC. - BAUAN | D35: Customer | F35: 0 | G35: 0 | H35: 0 | J35: 0 | K35: 0 | L35: 0 | N35: 0 | O35: 0 | P35: 0 | R35: 0 | S35: 0 | T35: 0 | V35: 0 | W35: 0
A36: 31 | B36: BAYAD CENTER - NBI | D36: No Billers | F36: 0 | G36: 0 | H36: 0 | J36: 0 | K36: 0 | L36: 0 | N36: 0 | O36: 0 | P36: 0 | R36: 0 | S36: 0 | T36: 0 | V36: 0 | W36: 0
A37: 32 | B37: BAYAN TELECOMMUNICATIONS INC | C37: BDO | D37: CusPart | F37: 0 | G37: 0 | H37: 0 | J37: 0 | K37: 0 | L37: 0 | N37: 0 | O37: 0 | P37: 0 | R37: 0 | S37: 0 | T37: 0 | V37: 0 | W37: 0
A38: 33 | B38: BBBROTHERS DV GEN. MDSE INC | C38: BDO ONLINE | D38: Customer | F38: 1 | G38: 9835 | H38: 30 | J38: 0 | K38: 0 | L38: 0 | N38: 1 | O38: 9835 | P38: 30 | R38: 0 | S38: 0 | T38: 0 | V38: 1 | W38: 9835
A39: 34 | B39: BBBROTHERS LAGUNA INC 001 | C39: BDO ONLINE | D39: Customer | F39: 0 | G39: 0 | H39: 0 | J39: 0 | K39: 0 | L39: 0 | N39: 0 | O39: 0 | P39: 0 | R39: 0 | S39: 0 | T39: 0 | V39: 0 | W39: 0
A40: 35 | B40: BBBROTHERS LAGUNA INC 002 | C40: BDO ONLINE | D40: Customer | F40: 0 | G40: 0 | H40: 0 | J40: 0 | K40: 0 | L40: 0 | N40: 0 | O40: 0 | P40: 0 | R40: 0 | S40: 0 | T40: 0 | V40: 0 | W40: 0
...

Sheet 30
A1: MLHUILLIER PHILIPPINES
A2: BILLS PAYMENT REPORT
A3: Report Date : AUGUST 2025
F4: MLKP7 | J4: Cancelled (web) | N4: Net Total Trxns | R4: Billed Amount | V4: Current Variance
A5: No. | B5: Partner's Name | C5: Banks | D5: CHARGING TYPE | F5: Vol | G5: Principal | H5: Charge | J5: Vol | K5: Principal | L5: Charge | N5: Vol | O5: Principal | P5: Charge | R5: Vol | S5: Amount | T5: Charge | V5: Vol | W5: Amount
A6: 1 | B6: 123 LENDING CORPORATION | C6: BDO | D6: Customer | F6: 6 | G6: 56049.33 | H6: 600 | J6: 0 | K6: 0 | L6: 0 | N6: 6 | O6: 56049.33 | P6: 600 | R6: 0 | S6: 0 | T6: 0 | V6: 6 | W6: 56049.33
A7: 2 | B7: A-1 MILLING CORPORATION | C7: METROBANK | D7: Customer | F7: 0 | G7: 0 | H7: 0 | J7: 0 | K7: 0 | L7: 0 | N7: 0 | O7: 0 | P7: 0 | R7: 0 | S7: 0 | T7: 0 | V7: 0 | W7: 0
A8: 3 | B8: A2M GLOBAL DISTRIBUTION INC. | C8: METROBANK | D8: Partner | F8: 6 | G8: 87272.07 | H8: 300 | J8: 0 | K8: 0 | L8: 0 | N8: 6 | O8: 87272.07 | P8: 300 | R8: 0 | S8: 0 | T8: 0 | V8: 6 | W8: 87272.07
A9: 4 | B9: ABEJO WATERS CORP - CEBU | C9: BPI ONLINE | D9: Customer | F9: 0 | G9: 0 | H9: 0 | J9: 0 | K9: 0 | L9: 0 | N9: 0 | O9: 0 | P9: 0 | R9: 0 | S9: 0 | T9: 0 | V9: 0 | W9: 0
A10: 5 | B10: ABEJO WATERS CORP - TALISAY | C10: CHINABANK | D10: Customer | F10: 0 | G10: 0 | H10: 0 | J10: 0 | K10: 0 | L10: 0 | N10: 0 | O10: 0 | P10: 0 | R10: 0 | S10: 0 | T10: 0 | V10: 0 | W10: 0
A11: 6 | B11: AEON CREDIT SERVICE PHIL INC. API | C11: METROBANK | D11: Customer | F11: 14 | G11: 39135.45 | H11: 210 | J11: 0 | K11: 0 | L11: 0 | N11: 14 | O11: 39135.45 | P11: 210 | R11: 0 | S11: 0 | T11: 0 | V11: 14 | W11: 39135.45
A12: 7 | B12: AF PAYMENTS (BEEP LOADING) | C12: BPI CHECK | D12: Customer | F12: 0 | G12: 0 | H12: 0 | J12: 0 | K12: 0 | L12: 0 | N12: 0 | O12: 0 | P12: 0 | R12: 0 | S12: 0 | T12: 0 | V12: 0 | W12: 0
A13: 8 | B13: AIA PHILIPPINES | C13: BPI | D13: Customer | F13: 10 | G13: 79233.91 | H13: 250 | J13: 0 | K13: 0 | L13: 0 | N13: 10 | O13: 79233.91 | P13: 250 | R13: 0 | S13: 0 | T13: 0 | V13: 10 | W13: 79233.91
A14: 9 | B14: AIR ASIA/ZEST AIR | C14: BDO | D14: Partner | F14: 6 | G14: 93851.55 | H14: 160 | J14: 0 | K14: 0 | L14: 0 | N14: 6 | O14: 93851.55 | P14: 160 | R14: 0 | S14: 0 | T14: 0 | V14: 6 | W14: 93851.55
A15: 10 | B15: AIR YOU GO TRAVEL PHILS CO. | C15: BDO | D15: Customer | F15: 0 | G15: 0 | H15: 0 | J15: 0 | K15: 0 | L15: 0 | N15: 0 | O15: 0 | P15: 0 | R15: 0 | S15: 0 | T15: 0 | V15: 0 | W15: 0
A16: 11 | B16: AKLAN CABLE NETWORK, INC. - LEMERY | D16: Customer | F16: 0 | G16: 0 | H16: 0 | J16: 0 | K16: 0 | L16: 0 | N16: 0 | O16: 0 | P16: 0 | R16: 0 | S16: 0 | T16: 0 | V16: 0 | W16: 0
A17: 12 | B17: ALFA- ALL FOOD ASIA, INC. | C17: METROBANK | D17: Customer | F17: 0 | G17: 0 | H17: 0 | J17: 0 | K17: 0 | L17: 0 | N17: 0 | O17: 0 | P17: 0 | R17: 0 | S17: 0 | T17: 0 | V17: 0 | W17: 0
A18: 13 | B18: AMBROSIA PHILS INC | C18: METROBANK | D18: Partner | F18: 58 | G18: 1379443.8 | H18: 1825 | J18: 0 | K18: 0 | L18: 0 | N18: 58 | O18: 1379443.8 | P18: 1825 | R18: 0 | S18: 0 | T18: 0 | V18: 58 | W18: 1379443.8
A19: 14 | B19: ANECO | C19: BPI | D19: Customer | F19: 5 | G19: 20349.54 | H19: 25 | J19: 0 | K19: 0 | L19: 0 | N19: 5 | O19: 20349.54 | P19: 25 | R19: 0 | S19: 0 | T19: 0 | V19: 5 | W19: 20349.54
A20: 15 | B20: ANECO COLLECTIONS | C20: BPI | D20: Customer | F20: 0 | G20: 0 | H20: 0 | J20: 0 | K20: 0 | L20: 0 | N20: 0 | O20: 0 | P20: 0 | R20: 0 | S20: 0 | T20: 0 | V20: 0 | W20: 0
A21: 16 | B21: ANGELES CITY WATER DISTRICT | C21: LANBANK | D21: Customer | F21: 0 | G21: 0 | H21: 0 | J21: 0 | K21: 0 | L21: 0 | N21: 0 | O21: 0 | P21: 0 | R21: 0 | S21: 0 | T21: 0 | V21: 0 | W21: 0
A22: 17 | B22: AQUA CENTRO MWPV CORP. | C22: BPI ONLINE | D22: CusPart | F22: 1 | G22: 2000 | H22: 7 | J22: 0 | K22: 0 | L22: 0 | N22: 1 | O22: 2000 | P22: 7 | R22: 0 | S22: 0 | T22: 0 | V22: 1 | W22: 2000
A23: 18 | B23: ASIALINK FINANCE CORPORATION | C23: BDO | D23: Partner M. | F23: 599 | G23: 12391964 | H23: 10080 | J23: 0 | K23: 0 | L23: 0 | N23: 599 | O23: 12391964 | P23: 10080 | R23: 0 | S23: 0 | T23: 0 | V23: 599 | W23: 12391964
A24: 19 | B24: ASIAN COLLEGE OF SCIENCE AND TECHNOLOGY FDN. INC. | C24: BPI ONLINE | D24: Customer | F24: 0 | G24: 0 | H24: 0 | J24: 0 | K24: 0 | L24: 0 | N24: 0 | O24: 0 | P24: 0 | R24: 0 | S24: 0 | T24: 0 | V24: 0 | W24: 0
A25: 20 | B25: ASIAN COLLEGE OF TECHNOLOGY (ACT) | D25: Customer | F25: 0 | G25: 0 | H25: 0 | J25: 0 | K25: 0 | L25: 0 | N25: 0 | O25: 0 | P25: 0 | R25: 0 | S25: 0 | T25: 0 | V25: 0 | W25: 0
A26: 21 | B26: ASIAN INTERNATIONAL SCHOOL OF AERONAUTICS AND TECHNOLOGY (AISAT) CORP. | C26: METROBANK | D26: Customer | F26: 1 | G26: 7700 | H26: 30 | J26: 0 | K26: 0 | L26: 0 | N26: 1 | O26: 7700 | P26: 30 | R26: 0 | S26: 0 | T26: 0 | V26: 1 | W26: 7700
A27: 22 | B27: ATENEO DE DAVAO UNIVERSITY | C27: PNB | D27: Customer | F27: 0 | G27: 0 | H27: 0 | J27: 0 | K27: 0 | L27: 0 | N27: 0 | O27: 0 | P27: 0 | R27: 0 | S27: 0 | T27: 0 | V27: 0 | W27: 0
A28: 23 | B28: ATENEO DE ZAMBOANGA UNIVERSITY | C28: METROBANK | D28: Customer | F28: 0 | G28: 0 | H28: 0 | J28: 0 | K28: 0 | L28: 0 | N28: 0 | O28: 0 | P28: 0 | R28: 0 | S28: 0 | T28: 0 | V28: 0 | W28: 0
A29: 24 | B29: ATLAS CEBU CORN MILL CORP | C29: CHINABANK | D29: Customer | F29: 5 | G29: 395290 | H29: 250 | J29: 0 | K29: 0 | L29: 0 | N29: 5 | O29: 395290 | P29: 250 | R29: 0 | S29: 0 | T29: 0 | V29: 5 | W29: 395290
A30: 25 | B30: BAKERS BEST MARKETING CORPORATION | C30: BPI | D30: Customer | F30: 2 | G30: 9079 | H30: 60 | J30: 0 | K30: 0 | L30: 0 | N30: 2 | O30: 9079 | P30: 60 | R30: 0 | S30: 0 | T30: 0 | V30: 2 | W30: 9079
A31: 26 | B31: BALAMBAN ENERZONE | D31: No Billers | F31: 0 | G31: 0 | H31: 0 | J31: 0 | K31: 0 | L31: 0 | N31: 0 | O31: 0 | P31: 0 | R31: 0 | S31: 0 | T31: 0 | V31: 0 | W31: 0
A32: 27 | B32: BALAMBAN WATER DISTRICT | C32: LANBANK | D32: Customer | F32: 8 | G32: 2636.05 | H32: 80 | J32: 0 | K32: 0 | L32: 0 | N32: 8 | O32: 2636.05 | P32: 80 | R32: 0 | S32: 0 | T32: 0 | V32: 8 | W32: 2636.05
A33: 28 | B33: BASIC WATER ENTERPRISES INC. | C33: METROBANK | D33: Partner | F33: 0 | G33: 0 | H33: 0 | J33: 0 | K33: 0 | L33: 0 | N33: 0 | O33: 0 | P33: 0 | R33: 0 | S33: 0 | T33: 0 | V33: 0 | W33: 0
A34: 29 | B34: BATANGAS CATV, INC. - BATANGAS | D34: Customer | F34: 0 | G34: 0 | H34: 0 | J34: 0 | K34: 0 | L34: 0 | N34: 0 | O34: 0 | P34: 0 | R34: 0 | S34: 0 | T34: 0 | V34: 0 | W34: 0
A35: 30 | B35: BATANGAS CATV, INC. - BAUAN | D35: Customer | F35: 0 | G35: 0 | H35: 0 | J35: 0 | K35: 0 | L35: 0 | N35: 0 | O35: 0 | P35: 0 | R35: 0 | S35: 0 | T35: 0 | V35: 0 | W35: 0
A36: 31 | B36: BAYAD CENTER - NBI | D36: No Billers | F36: 0 | G36: 0 | H36: 0 | J36: 0 | K36: 0 | L36: 0 | N36: 0 | O36: 0 | P36: 0 | R36: 0 | S36: 0 | T36: 0 | V36: 0 | W36: 0
A37: 32 | B37: BAYAN TELECOMMUNICATIONS INC | C37: BDO | D37: CusPart | F37: 0 | G37: 0 | H37: 0 | J37: 0 | K37: 0 | L37: 0 | N37: 0 | O37: 0 | P37: 0 | R37: 0 | S37: 0 | T37: 0 | V37: 0 | W37: 0
A38: 33 | B38: BBBROTHERS DV GEN. MDSE INC | C38: BDO ONLINE | D38: Customer | F38: 2 | G38: 22435 | H38: 60 | J38: 0 | K38: 0 | L38: 0 | N38: 2 | O38: 22435 | P38: 60 | R38: 0 | S38: 0 | T38: 0 | V38: 2 | W38: 22435
A39: 34 | B39: BBBROTHERS LAGUNA INC 001 | C39: BDO ONLINE | D39: Customer | F39: 0 | G39: 0 | H39: 0 | J39: 0 | K39: 0 | L39: 0 | N39: 0 | O39: 0 | P39: 0 | R39: 0 | S39: 0 | T39: 0 | V39: 0 | W39: 0
A40: 35 | B40: BBBROTHERS LAGUNA INC 002 | C40: BDO ONLINE | D40: Customer | F40: 0 | G40: 0 | H40: 0 | J40: 0 | K40: 0 | L40: 0 | N40: 0 | O40: 0 | P40: 0 | R40: 0 | S40: 0 | T40: 0 | V40: 0 | W40: 0
...

Sheet 31
A1: MLHUILLIER PHILIPPINES
A2: BILLS PAYMENT REPORT
A3: Report Date : July 31, 2025
F4: MLKP7 | J4: Cancelled (web) | N4: Net Total Trxns | R4: Billed Amount | V4: Current Variance
A5: No. | B5: Partner's Name | C5: Billers Name | D5: Banks | F5: Vol | G5: Principal | H5: Charge | J5: Vol | K5: Principal | L5: Charge | N5: Vol | O5: Principal | P5: Charge | R5: Vol | S5: Amount | T5: Charge | V5: Vol | W5: Amount
A6: 1 | B6: 123 LENDING CORPORATION | C6: BDO | D6: Customer | F6: 5 | G6: 43567.17 | H6: 500 | J6: 0 | K6: 0 | L6: 0 | N6: 5 | O6: 43567.17 | P6: 500 | R6: 17 | S6: 221714.16 | T6: 0 | V6: =N6-R6 -> -12 | W6: =O6-S6-T6 -> -178146.99
A7: 2 | B7: A-1 MILLING CORPORATION | C7: METROBANK | D7: Customer | F7: 0 | G7: 0 | H7: 0 | J7: 0 | K7: 0 | L7: 0 | N7: 0 | O7: 0 | P7: 0 | R7: 1 | S7: 111555 | T7: 0 | V7: =N7-R7 -> -1 | W7: =O7-S7-T7 -> -111555
A8: 3 | B8: A2M GLOBAL DISTRIBUTION INC. | C8: METROBANK | D8: Partner | F8: 0 | G8: 0 | H8: 0 | J8: 0 | K8: 0 | L8: 0 | N8: 0 | O8: 0 | P8: 0 | R8: 3 | S8: 101795.69 | T8: 0 | V8: =N8-R8 -> -3 | W8: =O8-S8-T8 -> -101795.69
A9: 4 | B9: ABEJO WATERS CORP - CEBU | C9: BPI ONLINE | D9: Customer | F9: 0 | G9: 0 | H9: 0 | J9: 0 | K9: 0 | L9: 0 | N9: 0 | O9: 0 | P9: 0 | R9: 0 | S9: 0 | T9: 0 | V9: =N9-R9 -> 0 | W9: =O9-S9-T9 -> 0
A10: 5 | B10: ABEJO WATERS CORP - TALISAY | C10: CHINABANK | D10: Customer | F10: 0 | G10: 0 | H10: 0 | J10: 0 | K10: 0 | L10: 0 | N10: 0 | O10: 0 | P10: 0 | R10: 0 | S10: 0 | T10: 0 | V10: =N10-R10 -> 0 | W10: =O10-S10-T10 -> 0
A11: 6 | B11: AEON CREDIT SERVICE PHIL INC. API | C11: METROBANK | D11: Customer | F11: 15 | G11: 35205.94 | H11: 225 | J11: 0 | K11: 0 | L11: 0 | N11: 15 | O11: 35205.94 | P11: 225 | R11: 19 | S11: 42737.72 | T11: 0 | V11: =N11-R11 -> -4 | W11: =O11-S11-T11 -> -7531.78
A12: 7 | B12: AF PAYMENTS (BEEP LOADING) | C12: BPI CHECK | D12: Customer | F12: 0 | G12: 0 | H12: 0 | J12: 0 | K12: 0 | L12: 0 | N12: 0 | O12: 0 | P12: 0 | R12: 0 | S12: 0 | T12: 0 | V12: =N12-R12 -> 0 | W12: =O12-S12-T12 -> 0
A13: 8 | B13: AIA PHILIPPINES | C13: BPI | D13: Customer | F13: 8 | G13: 51123.76 | H13: 200 | J13: 0 | K13: 0 | L13: 0 | N13: 8 | O13: 51123.76 | P13: 200 | R13: 9 | S13: 66899.46 | T13: 0 | V13: =N13-R13 -> -1 | W13: =O13-S13-T13 -> -15775.7
A14: 9 | B14: AIR ASIA/ZEST AIR | C14: BDO | D14: Partner | F14: 3 | G14: 20308.88 | H14: 60 | J14: 0 | K14: 0 | L14: 0 | N14: 3 | O14: 20308.88 | P14: 60 | R14: 6 | S14: 20919.43 | T14: 120 | V14: =N14-R14 -> -3 | W14: =O14-S14-T14 -> -730.55
A15: 10 | B15: AIR YOU GO TRAVEL PHILS CO. | C15: BDO | D15: Customer | F15: 0 | G15: 0 | H15: 0 | J15: 0 | K15: 0 | L15: 0 | N15: 0 | O15: 0 | P15: 0 | R15: 0 | S15: 0 | T15: 0 | V15: =N15-R15 -> 0 | W15: =O15-S15-T15 -> 0
A16: 11 | B16: AKLAN CABLE NETWORK, INC. - LEMERY | D16: Customer | F16: 0 | G16: 0 | H16: 0 | J16: 0 | K16: 0 | L16: 0 | N16: 0 | O16: 0 | P16: 0 | R16: 0 | S16: 0 | T16: 0 | V16: =N16-R16 -> 0 | W16: =O16-S16-T16 -> 0
A17: 12 | B17: ALFA- ALL FOOD ASIA, INC. | C17: METROBANK | D17: Customer | F17: 0 | G17: 0 | H17: 0 | J17: 0 | K17: 0 | L17: 0 | N17: 0 | O17: 0 | P17: 0 | R17: 0 | S17: 0 | T17: 0 | V17: =N17-R17 -> 0 | W17: =O17-S17-T17 -> 0
A18: 13 | B18: AMBROSIA PHILS INC | C18: METROBANK | D18: Partner | F18: 56 | G18: 1412224.5 | H18: 1825 | J18: 0 | K18: 0 | L18: 0 | N18: 56 | O18: 1412224.5 | P18: 1825 | R18: 57 | S18: 1176187.2 | T18: 1675 | V18: =N18-R18 -> -1 | W18: =O18-S18-T18 -> 234362.25
A19: 14 | B19: ANECO | C19: BPI | D19: Customer | F19: 5 | G19: 3773.42 | H19: 25 | J19: 0 | K19: 0 | L19: 0 | N19: 5 | O19: 3773.42 | P19: 25 | R19: 16 | S19: 60110.21 | T19: 0 | V19: =N19-R19 -> -11 | W19: =O19-S19-T19 -> -56336.79
A20: 15 | B20: ANECO COLLECTIONS | C20: BPI | D20: Customer | F20: 0 | G20: 0 | H20: 0 | J20: 0 | K20: 0 | L20: 0 | N20: 0 | O20: 0 | P20: 0 | R20: 0 | S20: 0 | T20: 0 | V20: =N20-R20 -> 0 | W20: =O20-S20-T20 -> 0
A21: 16 | B21: ANGELES CITY WATER DISTRICT | C21: LANBANK | D21: Customer | F21: 0 | G21: 0 | H21: 0 | J21: 0 | K21: 0 | L21: 0 | N21: 0 | O21: 0 | P21: 0 | R21: 0 | S21: 0 | T21: 0 | V21: =N21-R21 -> 0 | W21: =O21-S21-T21 -> 0
A22: 17 | B22: AQUA CENTRO MWPV CORP. | C22: BPI ONLINE | D22: CusPart | F22: 1 | G22: 500 | H22: 7 | J22: 0 | K22: 0 | L22: 0 | N22: 1 | O22: 500 | P22: 7 | R22: 0 | S22: 0 | T22: 0 | V22: =N22-R22 -> 1 | W22: =O22-S22-T22 -> 500
A23: 18 | B23: ASIALINK FINANCE CORPORATION | C23: BDO | D23: Partner M. | F23: 284 | G23: 5061561.2 | H23: 4656 | J23: 0 | K23: 0 | L23: 0 | N23: 284 | O23: 5061561.2 | P23: 4656 | R23: 461 | S23: 9729177.5 | T23: 0 | V23: =N23-R23 -> -177 | W23: =O23-S23-T23 -> -4667616.3
A24: 19 | B24: ASIAN COLLEGE OF SCIENCE AND TECHNOLOGY FDN. INC. | C24: BPI ONLINE | D24: Customer | F24: 0 | G24: 0 | H24: 0 | J24: 0 | K24: 0 | L24: 0 | N24: 0 | O24: 0 | P24: 0 | R24: 0 | S24: 0 | T24: 0 | V24: =N24-R24 -> 0 | W24: =O24-S24-T24 -> 0
A25: 20 | B25: ASIAN COLLEGE OF TECHNOLOGY (ACT) | D25: Customer | F25: 0 | G25: 0 | H25: 0 | J25: 0 | K25: 0 | L25: 0 | N25: 0 | O25: 0 | P25: 0 | R25: 0 | S25: 0 | T25: 0 | V25: =N25-R25 -> 0 | W25: =O25-S25-T25 -> 0
A26: 21 | B26: ASIAN INTERNATIONAL SCHOOL OF AERONAUTICS AND TECHNOLOGY (AISAT) CORP. | C26: METROBANK | D26: Customer | F26: 1 | G26: 10500 | H26: 30 | J26: 0 | K26: 0 | L26: 0 | N26: 1 | O26: 10500 | P26: 30 | R26: 1 | S26: 19115 | T26: 0 | V26: =N26-R26 -> 0 | W26: =O26-S26-T26 -> -8615
A27: 22 | B27: ATENEO DE DAVAO UNIVERSITY | C27: PNB | D27: Customer | F27: 0 | G27: 0 | H27: 0 | J27: 0 | K27: 0 | L27: 0 | N27: 0 | O27: 0 | P27: 0 | R27: 0 | S27: 0 | T27: 0 | V27: =N27-R27 -> 0 | W27: =O27-S27-T27 -> 0
A28: 23 | B28: ATENEO DE ZAMBOANGA UNIVERSITY | C28: METROBANK | D28: Customer | F28: 0 | G28: 0 | H28: 0 | J28: 0 | K28: 0 | L28: 0 | N28: 0 | O28: 0 | P28: 0 | R28: 0 | S28: 0 | T28: 0 | V28: =N28-R28 -> 0 | W28: =O28-S28-T28 -> 0
A29: 24 | B29: ATLAS CEBU CORN MILL CORP | C29: CHINABANK | D29: Customer | F29: 0 | G29: 0 | H29: 0 | J29: 0 | K29: 0 | L29: 0 | N29: 0 | O29: 0 | P29: 0 | R29: 1 | S29: 36725 | T29: 0 | V29: =N29-R29 -> -1 | W29: =O29-S29-T29 -> -36725
A30: 25 | B30: BAKERS BEST MARKETING CORPORATION | C30: BPI | D30: Customer | F30: 2 | G30: 20200 | H30: 60 | J30: 0 | K30: 0 | L30: 0 | N30: 2 | O30: 20200 | P30: 60 | R30: 4 | S30: 18214 | T30: 0 | V30: =N30-R30 -> -2 | W30: =O30-S30-T30 -> 1986
A31: 26 | B31: BALAMBAN ENERZONE | D31: No Billers | F31: 0 | G31: 0 | H31: 0 | J31: 0 | K31: 0 | L31: 0 | N31: 0 | O31: 0 | P31: 0 | R31: 0 | S31: 0 | T31: 0 | V31: =N31-R31 -> 0 | W31: =O31-S31-T31 -> 0
A32: 27 | B32: BALAMBAN WATER DISTRICT | C32: LANBANK | D32: Customer | F32: 5 | G32: 1912.75 | H32: 50 | J32: 0 | K32: 0 | L32: 0 | N32: 5 | O32: 1912.75 | P32: 50 | R32: 0 | S32: 0 | T32: 0 | V32: =N32-R32 -> 5 | W32: =O32-S32-T32 -> 1912.75
A33: 28 | B33: BASIC WATER ENTERPRISES INC. | C33: METROBANK | D33: Partner | F33: 0 | G33: 0 | H33: 0 | J33: 0 | K33: 0 | L33: 0 | N33: 0 | O33: 0 | P33: 0 | R33: 0 | S33: 0 | T33: 0 | V33: =N33-R33 -> 0 | W33: =O33-S33-T33 -> 0
A34: 29 | B34: BATANGAS CATV, INC. - BATANGAS | D34: Customer | F34: 0 | G34: 0 | H34: 0 | J34: 0 | K34: 0 | L34: 0 | N34: 0 | O34: 0 | P34: 0 | R34: 0 | S34: 0 | T34: 0 | V34: =N34-R34 -> 0 | W34: =O34-S34-T34 -> 0
A35: 30 | B35: BATANGAS CATV, INC. - BAUAN | D35: Customer | F35: 0 | G35: 0 | H35: 0 | J35: 0 | K35: 0 | L35: 0 | N35: 0 | O35: 0 | P35: 0 | R35: 1 | S35: 1830 | T35: 0 | V35: =N35-R35 -> -1 | W35: =O35-S35-T35 -> -1830
A36: 31 | B36: BAYAD CENTER - NBI | D36: No Billers | F36: 0 | G36: 0 | H36: 0 | J36: 0 | K36: 0 | L36: 0 | N36: 0 | O36: 0 | P36: 0 | R36: 0 | S36: 0 | T36: 0 | V36: =N36-R36 -> 0 | W36: =O36-S36-T36 -> 0
A37: 32 | B37: BAYAN TELECOMMUNICATIONS INC | C37: BDO | D37: CusPart | F37: 0 | G37: 0 | H37: 0 | J37: 0 | K37: 0 | L37: 0 | N37: 0 | O37: 0 | P37: 0 | R37: 0 | S37: 0 | T37: 0 | V37: =N37-R37 -> 0 | W37: =O37-S37-T37 -> 0
A38: 33 | B38: BBBROTHERS DV GEN. MDSE INC | C38: BDO ONLINE | D38: Customer | F38: 2 | G38: 25895 | H38: 60 | J38: 0 | K38: 0 | L38: 0 | N38: 2 | O38: 25895 | P38: 60 | R38: 0 | S38: 0 | T38: 0 | V38: =N38-R38 -> 2 | W38: =O38-S38-T38 -> 25895
A39: 34 | B39: BBBROTHERS LAGUNA INC 001 | C39: BDO ONLINE | D39: Customer | F39: 0 | G39: 0 | H39: 0 | J39: 0 | K39: 0 | L39: 0 | N39: 0 | O39: 0 | P39: 0 | R39: 0 | S39: 0 | T39: 0 | V39: =N39-R39 -> 0 | W39: =O39-S39-T39 -> 0
A40: 35 | B40: BBBROTHERS LAGUNA INC 002 | C40: BDO ONLINE | D40: Customer | F40: 0 | G40: 0 | H40: 0 | J40: 0 | K40: 0 | L40: 0 | N40: 0 | O40: 0 | P40: 0 | R40: 7 | S40: 122268 | T40: 0 | V40: =N40-R40 -> -7 | W40: =O40-S40-T40 -> -122268
...

Sheet AP AR
A1: MLHUILLIER PHILIPPINES
A2: BILLS PAYMENT REPORT
A3: Report Date : August 31, 2025
F4: MLKP7 | J4: Cancelled (web) | N4: Net Total Trxns | R4: Billed Amount | V4: Current Variance | Y4: Running Balance
A5: No. | B5: Partner's Name | C5: Billers Name | D5: Banks | F5: Vol | G5: Principal | H5: Charge | J5: Vol | K5: Principal | L5: Charge | N5: Vol | O5: Principal | P5: Charge | R5: Vol | S5: Amount | T5: Charge | V5: Vol | W5: Amount | Y5: Vol | Z5: Amount | AB5: August 31, 2025 | AD5: Paid Service Charge | AF5: Accounts Payable to Partner | AG5: Service Charge | AH5: BPW undeducted | AI5: BPX undeducted | AJ5: Audit findings | AK5: Banks | AL5: Others | AM5: Accounts Receivable from Partner | AN5: Balances as of August 31, 2025
A6: 1 | B6: 123 LENDING CORPORATION | C6: BDO | D6: Customer | F6: =+'29'!F6+'30'!F6+'31'!F6 -> 19 | G6: =+'29'!G6+'30'!G6+'31'!G6 -> 209430.5 | H6: =+'29'!H6+'30'!H6+'31'!H6 -> 1900 | J6: =+'29'!J6+'30'!J6+'31'!J6 -> 0 | K6: =+'29'!K6+'30'!K6+'31'!K6 -> 0 | L6: =+'29'!L6+'30'!L6+'31'!L6 -> 0 | M6: =+'29'!M6+'30'!M6+'31'!M6 -> 0 | N6: =+'29'!N6+'30'!N6+'31'!N6 -> 19 | O6: =+'29'!O6+'30'!O6+'31'!O6 -> 209430.5 | P6: =+'29'!P6+'30'!P6+'31'!P6 -> 1900 | R6: 19 | S6: 209430.5 | T6: 0 | V6: =N6-R6 -> 0 | W6: =O6-S6 -> 0 | Y6: =V6 -> 0 | Z6: =W6 -> 0 | AB6: =O6 -> 209430.5 | AF6: =AB6-AD6 -> 209430.5 | AM6: =SUM(AG6:AL6) -> 0 | AN6: =AF6-AM6 -> 209430.5
A7: 2 | B7: A-1 MILLING CORPORATION | C7: METROBANK | D7: Customer | F7: =+'29'!F7+'30'!F7+'31'!F7 -> 4 | G7: =+'29'!G7+'30'!G7+'31'!G7 -> 651400 | H7: =+'29'!H7+'30'!H7+'31'!H7 -> 350 | J7: =+'29'!J7+'30'!J7+'31'!J7 -> 0 | K7: =+'29'!K7+'30'!K7+'31'!K7 -> 0 | L7: =+'29'!L7+'30'!L7+'31'!L7 -> 0 | N7: =+'29'!N7+'30'!N7+'31'!N7 -> 4 | O7: =+'29'!O7+'30'!O7+'31'!O7 -> 651400 | P7: =+'29'!P7+'30'!P7+'31'!P7 -> 350 | R7: 4 | S7: 651400 | T7: 0 | V7: =N7-R7 -> 0 | W7: =O7-S7 -> 0 | Y7: =V7 -> 0 | Z7: =W7 -> 0 | AB7: =O7 -> 651400 | AF7: =AB7-AD7 -> 651400 | AM7: =SUM(AG7:AL7) -> 0 | AN7: =AF7-AM7 -> 651400
A8: 3 | B8: A2M GLOBAL DISTRIBUTION INC. | C8: METROBANK | D8: Partner | F8: =+'29'!F8+'30'!F8+'31'!F8 -> 12 | G8: =+'29'!G8+'30'!G8+'31'!G8 -> 185249.89 | H8: =+'29'!H8+'30'!H8+'31'!H8 -> 600 | J8: =+'29'!J8+'30'!J8+'31'!J8 -> 0 | K8: =+'29'!K8+'30'!K8+'31'!K8 -> 0 | L8: =+'29'!L8+'30'!L8+'31'!L8 -> 0 | N8: =+'29'!N8+'30'!N8+'31'!N8 -> 12 | O8: =+'29'!O8+'30'!O8+'31'!O8 -> 185249.89 | P8: =+'29'!P8+'30'!P8+'31'!P8 -> 600 | R8: 12 | S8: 185249.89 | T8: 0 | V8: =N8-R8 -> 0 | W8: =O8-S8 -> 0 | Y8: =V8 -> 0 | Z8: =W8 -> 0 | AB8: =O8 -> 185249.89 | AF8: =AB8-AD8 -> 185249.89 | AM8: =SUM(AG8:AL8) -> 0 | AN8: =AF8-AM8 -> 185249.89
A9: 4 | B9: ABEJO WATERS CORP - CEBU | C9: BPI ONLINE | D9: Customer | F9: =+'29'!F9+'30'!F9+'31'!F9 -> 0 | G9: =+'29'!G9+'30'!G9+'31'!G9 -> 0 | H9: =+'29'!H9+'30'!H9+'31'!H9 -> 0 | J9: =+'29'!J9+'30'!J9+'31'!J9 -> 0 | K9: =+'29'!K9+'30'!K9+'31'!K9 -> 0 | L9: =+'29'!L9+'30'!L9+'31'!L9 -> 0 | N9: =+'29'!N9+'30'!N9+'31'!N9 -> 0 | O9: =+'29'!O9+'30'!O9+'31'!O9 -> 0 | P9: =+'29'!P9+'30'!P9+'31'!P9 -> 0 | R9: 0 | S9: 0 | T9: 0 | V9: =N9-R9 -> 0 | W9: =O9-S9 -> 0 | Y9: =V9 -> 0 | Z9: =W9 -> 0 | AB9: =O9 -> 0 | AF9: =AB9-AD9 -> 0 | AM9: =SUM(AG9:AL9) -> 0 | AN9: =AF9-AM9 -> 0
A10: 5 | B10: ABEJO WATERS CORP - TALISAY | C10: CHINABANK | D10: Customer | F10: =+'29'!F10+'30'!F10+'31'!F10 -> 0 | G10: =+'29'!G10+'30'!G10+'31'!G10 -> 0 | H10: =+'29'!H10+'30'!H10+'31'!H10 -> 0 | J10: =+'29'!J10+'30'!J10+'31'!J10 -> 0 | K10: =+'29'!K10+'30'!K10+'31'!K10 -> 0 | L10: =+'29'!L10+'30'!L10+'31'!L10 -> 0 | N10: =+'29'!N10+'30'!N10+'31'!N10 -> 0 | O10: =+'29'!O10+'30'!O10+'31'!O10 -> 0 | P10: =+'29'!P10+'30'!P10+'31'!P10 -> 0 | R10: 0 | S10: 0 | T10: 0 | V10: =N10-R10 -> 0 | W10: =O10-S10 -> 0 | Y10: =V10 -> 0 | Z10: =W10 -> 0 | AB10: =O10 -> 0 | AF10: =AB10-AD10 -> 0 | AM10: =SUM(AG10:AL10) -> 0 | AN10: =AF10-AM10 -> 0
A11: 6 | B11: AEON CREDIT SERVICE PHIL INC. API | C11: METROBANK | D11: Customer | F11: =+'29'!F11+'30'!F11+'31'!F11 -> 36 | G11: =+'29'!G11+'30'!G11+'31'!G11 -> 91903.77 | H11: =+'29'!H11+'30'!H11+'31'!H11 -> 540 | J11: =+'29'!J11+'30'!J11+'31'!J11 -> 0 | K11: =+'29'!K11+'30'!K11+'31'!K11 -> 0 | L11: =+'29'!L11+'30'!L11+'31'!L11 -> 0 | N11: =+'29'!N11+'30'!N11+'31'!N11 -> 36 | O11: =+'29'!O11+'30'!O11+'31'!O11 -> 91903.77 | P11: =+'29'!P11+'30'!P11+'31'!P11 -> 540 | R11: 36 | S11: 91903.77 | T11: 0 | V11: =N11-R11 -> 0 | W11: =O11-S11 -> 0 | Y11: =V11 -> 0 | Z11: =W11 -> 0 | AB11: =O11 -> 91903.77 | AF11: =AB11-AD11 -> 91903.77 | AM11: =SUM(AG11:AL11) -> 0 | AN11: =AF11-AM11 -> 91903.77
A12: 7 | B12: AF PAYMENTS (BEEP LOADING) | C12: BPI CHECK | D12: Customer | F12: =+'29'!F12+'30'!F12+'31'!F12 -> 0 | G12: =+'29'!G12+'30'!G12+'31'!G12 -> 0 | H12: =+'29'!H12+'30'!H12+'31'!H12 -> 0 | J12: =+'29'!J12+'30'!J12+'31'!J12 -> 0 | K12: =+'29'!K12+'30'!K12+'31'!K12 -> 0 | L12: =+'29'!L12+'30'!L12+'31'!L12 -> 0 | N12: =+'29'!N12+'30'!N12+'31'!N12 -> 0 | O12: =+'29'!O12+'30'!O12+'31'!O12 -> 0 | P12: =+'29'!P12+'30'!P12+'31'!P12 -> 0 | R12: 0 | S12: 0 | T12: 0 | V12: =N12-R12 -> 0 | W12: =O12-S12 -> 0 | Y12: =V12 -> 0 | Z12: =W12 -> 0 | AB12: =O12 -> 0 | AF12: =AB12-AD12 -> 0 | AM12: =SUM(AG12:AL12) -> 0 | AN12: =AF12-AM12 -> 0
A13: 8 | B13: AIA PHILIPPINES | C13: BPI | D13: Customer | F13: =+'29'!F13+'30'!F13+'31'!F13 -> 26 | G13: =+'29'!G13+'30'!G13+'31'!G13 -> 210044.67 | H13: =+'29'!H13+'30'!H13+'31'!H13 -> 650 | J13: =+'29'!J13+'30'!J13+'31'!J13 -> 0 | K13: =+'29'!K13+'30'!K13+'31'!K13 -> 0 | L13: =+'29'!L13+'30'!L13+'31'!L13 -> 0 | N13: =+'29'!N13+'30'!N13+'31'!N13 -> 26 | O13: =+'29'!O13+'30'!O13+'31'!O13 -> 210044.67 | P13: =+'29'!P13+'30'!P13+'31'!P13 -> 650 | R13: 26 | S13: 210044.67 | T13: 0 | V13: =N13-R13 -> 0 | W13: =O13-S13 -> 0 | Y13: =V13 -> 0 | Z13: =W13 -> 0 | AB13: =O13 -> 210044.67 | AF13: =AB13-AD13 -> 210044.67 | AM13: =SUM(AG13:AL13) -> 0 | AN13: =AF13-AM13 -> 210044.67
A14: 9 | B14: AIR ASIA/ZEST AIR | C14: BDO | D14: Partner | F14: =+'29'!F14+'30'!F14+'31'!F14 -> 13 | G14: =+'29'!G14+'30'!G14+'31'!G14 -> 131749.39 | H14: =+'29'!H14+'30'!H14+'31'!H14 -> 300 | J14: =+'29'!J14+'30'!J14+'31'!J14 -> 0 | K14: =+'29'!K14+'30'!K14+'31'!K14 -> 0 | L14: =+'29'!L14+'30'!L14+'31'!L14 -> 0 | N14: =+'29'!N14+'30'!N14+'31'!N14 -> 13 | O14: =+'29'!O14+'30'!O14+'31'!O14 -> 131749.39 | P14: =+'29'!P14+'30'!P14+'31'!P14 -> 300 | R14: 13 | S14: 131449.39 | T14: 300 | V14: =N14-R14 -> 0 | W14: =O14-S14 -> 300 | Y14: =V14 -> 0 | Z14: =W14 -> 300 | AB14: =O14 -> 131749.39 | AF14: =AB14-AD14 -> 131749.39 | AM14: =SUM(AG14:AL14) -> 0 | AN14: =AF14-AM14 -> 131749.39
A15: 10 | B15: AIR YOU GO TRAVEL PHILS CO. | C15: BDO | D15: Customer | F15: =+'29'!F15+'30'!F15+'31'!F15 -> 0 | G15: =+'29'!G15+'30'!G15+'31'!G15 -> 0 | H15: =+'29'!H15+'30'!H15+'31'!H15 -> 0 | J15: =+'29'!J15+'30'!J15+'31'!J15 -> 0 | K15: =+'29'!K15+'30'!K15+'31'!K15 -> 0 | L15: =+'29'!L15+'30'!L15+'31'!L15 -> 0 | N15: =+'29'!N15+'30'!N15+'31'!N15 -> 0 | O15: =+'29'!O15+'30'!O15+'31'!O15 -> 0 | P15: =+'29'!P15+'30'!P15+'31'!P15 -> 0 | R15: 0 | S15: 0 | T15: 0 | V15: =N15-R15 -> 0 | W15: =O15-S15 -> 0 | Y15: =V15 -> 0 | Z15: =W15 -> 0 | AB15: =O15 -> 0 | AF15: =AB15-AD15 -> 0 | AM15: =SUM(AG15:AL15) -> 0 | AN15: =AF15-AM15 -> 0
A16: 11 | B16: AKLAN CABLE NETWORK, INC. - LEMERY | D16: Customer | F16: =+'29'!F16+'30'!F16+'31'!F16 -> 0 | G16: =+'29'!G16+'30'!G16+'31'!G16 -> 0 | H16: =+'29'!H16+'30'!H16+'31'!H16 -> 0 | J16: =+'29'!J16+'30'!J16+'31'!J16 -> 0 | K16: =+'29'!K16+'30'!K16+'31'!K16 -> 0 | L16: =+'29'!L16+'30'!L16+'31'!L16 -> 0 | N16: =+'29'!N16+'30'!N16+'31'!N16 -> 0 | O16: =+'29'!O16+'30'!O16+'31'!O16 -> 0 | P16: =+'29'!P16+'30'!P16+'31'!P16 -> 0 | R16: 0 | S16: 0 | T16: 0 | V16: =N16-R16 -> 0 | W16: =O16-S16 -> 0 | Y16: =V16 -> 0 | Z16: =W16 -> 0 | AB16: =O16 -> 0 | AF16: =AB16-AD16 -> 0 | AM16: =SUM(AG16:AL16) -> 0 | AN16: =AF16-AM16 -> 0
A17: 12 | B17: ALFA- ALL FOOD ASIA, INC. | C17: METROBANK | D17: Customer | F17: =+'29'!F17+'30'!F17+'31'!F17 -> 0 | G17: =+'29'!G17+'30'!G17+'31'!G17 -> 0 | H17: =+'29'!H17+'30'!H17+'31'!H17 -> 0 | J17: =+'29'!J17+'30'!J17+'31'!J17 -> 0 | K17: =+'29'!K17+'30'!K17+'31'!K17 -> 0 | L17: =+'29'!L17+'30'!L17+'31'!L17 -> 0 | N17: =+'29'!N17+'30'!N17+'31'!N17 -> 0 | O17: =+'29'!O17+'30'!O17+'31'!O17 -> 0 | P17: =+'29'!P17+'30'!P17+'31'!P17 -> 0 | R17: 0 | S17: 0 | T17: 0 | V17: =N17-R17 -> 0 | W17: =O17-S17 -> 0 | Y17: =V17 -> 0 | Z17: =W17 -> 0 | AB17: =O17 -> 0 | AF17: =AB17-AD17 -> 0 | AM17: =SUM(AG17:AL17) -> 0 | AN17: =AF17-AM17 -> 0
A18: 13 | B18: AMBROSIA PHILS INC | C18: METROBANK | D18: Partner | F18: =+'29'!F18+'30'!F18+'31'!F18 -> 170 | G18: =+'29'!G18+'30'!G18+'31'!G18 -> 3947448.5 | H18: =+'29'!H18+'30'!H18+'31'!H18 -> 5300 | J18: =+'29'!J18+'30'!J18+'31'!J18 -> 0 | K18: =+'29'!K18+'30'!K18+'31'!K18 -> 0 | L18: =+'29'!L18+'30'!L18+'31'!L18 -> 0 | N18: =+'29'!N18+'30'!N18+'31'!N18 -> 170 | O18: =+'29'!O18+'30'!O18+'31'!O18 -> 3947448.5 | P18: =+'29'!P18+'30'!P18+'31'!P18 -> 5300 | R18: 170 | S18: 3942148.5 | T18: 5300 | V18: =N18-R18 -> 0 | W18: =O18-S18 -> 5300 | Y18: =V18 -> 0 | Z18: =W18 -> 5300 | AB18: =O18 -> 3947448.5 | AF18: =AB18-AD18 -> 3947448.5 | AM18: =SUM(AG18:AL18) -> 0 | AN18: =AF18-AM18 -> 3947448.5
A19: 14 | B19: ANECO | C19: BPI | D19: Customer | F19: =+'29'!F19+'30'!F19+'31'!F19 -> 21 | G19: =+'29'!G19+'30'!G19+'31'!G19 -> 60905.99 | H19: =+'29'!H19+'30'!H19+'31'!H19 -> 105 | J19: =+'29'!J19+'30'!J19+'31'!J19 -> 0 | K19: =+'29'!K19+'30'!K19+'31'!K19 -> 0 | L19: =+'29'!L19+'30'!L19+'31'!L19 -> 0 | N19: =+'29'!N19+'30'!N19+'31'!N19 -> 21 | O19: =+'29'!O19+'30'!O19+'31'!O19 -> 60905.99 | P19: =+'29'!P19+'30'!P19+'31'!P19 -> 105 | R19: 21 | S19: 60905.99 | T19: 0 | V19: =N19-R19 -> 0 | W19: =O19-S19 -> 0 | Y19: =V19 -> 0 | Z19: =W19 -> 0 | AB19: =O19 -> 60905.99 | AD19: 1866.0714 | AF19: =AB19-AD19 -> 59039.919 | AG19: 4169.1964 | AM19: =SUM(AG19:AL19) -> 4169.1964 | AN19: =AF19-AM19 -> 54870.722
A20: 15 | B20: ANECO COLLECTIONS | C20: BPI | D20: Customer | F20: =+'29'!F20+'30'!F20+'31'!F20 -> 0 | G20: =+'29'!G20+'30'!G20+'31'!G20 -> 0 | H20: =+'29'!H20+'30'!H20+'31'!H20 -> 0 | J20: =+'29'!J20+'30'!J20+'31'!J20 -> 0 | K20: =+'29'!K20+'30'!K20+'31'!K20 -> 0 | L20: =+'29'!L20+'30'!L20+'31'!L20 -> 0 | N20: =+'29'!N20+'30'!N20+'31'!N20 -> 0 | O20: =+'29'!O20+'30'!O20+'31'!O20 -> 0 | P20: =+'29'!P20+'30'!P20+'31'!P20 -> 0 | R20: 0 | S20: 0 | T20: 0 | V20: =N20-R20 -> 0 | W20: =O20-S20 -> 0 | Y20: =V20 -> 0 | Z20: =W20 -> 0 | AB20: =O20 -> 0 | AF20: =AB20-AD20 -> 0 | AG20: 58.928571 | AM20: =SUM(AG20:AL20) -> 58.928571 | AN20: =AF20-AM20 -> -58.928571
A21: 16 | B21: ANGELES CITY WATER DISTRICT | C21: LANBANK | D21: Customer | F21: =+'29'!F21+'30'!F21+'31'!F21 -> 0 | G21: =+'29'!G21+'30'!G21+'31'!G21 -> 0 | H21: =+'29'!H21+'30'!H21+'31'!H21 -> 0 | J21: =+'29'!J21+'30'!J21+'31'!J21 -> 0 | K21: =+'29'!K21+'30'!K21+'31'!K21 -> 0 | L21: =+'29'!L21+'30'!L21+'31'!L21 -> 0 | N21: =+'29'!N21+'30'!N21+'31'!N21 -> 0 | O21: =+'29'!O21+'30'!O21+'31'!O21 -> 0 | P21: =+'29'!P21+'30'!P21+'31'!P21 -> 0 | R21: 0 | S21: 0 | T21: 0 | V21: =N21-R21 -> 0 | W21: =O21-S21 -> 0 | Y21: =V21 -> 0 | Z21: =W21 -> 0 | AB21: =O21 -> 0 | AF21: =AB21-AD21 -> 0 | AM21: =SUM(AG21:AL21) -> 0 | AN21: =AF21-AM21 -> 0
A22: 17 | B22: AQUA CENTRO MWPV CORP. | C22: BPI ONLINE | D22: CusPart | F22: =+'29'!F22+'30'!F22+'31'!F22 -> 2 | G22: =+'29'!G22+'30'!G22+'31'!G22 -> 2500 | H22: =+'29'!H22+'30'!H22+'31'!H22 -> 14 | J22: =+'29'!J22+'30'!J22+'31'!J22 -> 0 | K22: =+'29'!K22+'30'!K22+'31'!K22 -> 0 | L22: =+'29'!L22+'30'!L22+'31'!L22 -> 0 | N22: =+'29'!N22+'30'!N22+'31'!N22 -> 2 | O22: =+'29'!O22+'30'!O22+'31'!O22 -> 2500 | P22: =+'29'!P22+'30'!P22+'31'!P22 -> 14 | R22: 2 | S22: 2500 | T22: 0 | V22: =N22-R22 -> 0 | W22: =O22-S22 -> 0 | Y22: =V22 -> 0 | Z22: =W22 -> 0 | AB22: =O22 -> 2500 | AF22: =AB22-AD22 -> 2500 | AM22: =SUM(AG22:AL22) -> 0 | AN22: =AF22-AM22 -> 2500
A23: 18 | B23: ASIALINK FINANCE CORPORATION | C23: BDO | D23: Partner M. | F23: =+'29'!F23+'30'!F23+'31'!F23 -> 1488 | G23: =+'29'!G23+'30'!G23+'31'!G23 -> 29805467 | H23: =+'29'!H23+'30'!H23+'31'!H23 -> 24912 | J23: =+'29'!J23+'30'!J23+'31'!J23 -> 0 | K23: =+'29'!K23+'30'!K23+'31'!K23 -> 0 | L23: =+'29'!L23+'30'!L23+'31'!L23 -> 0 | N23: =+'29'!N23+'30'!N23+'31'!N23 -> 1488 | O23: =+'29'!O23+'30'!O23+'31'!O23 -> 29805467 | P23: =+'29'!P23+'30'!P23+'31'!P23 -> 24912 | R23: 1488 | S23: 29805467 | T23: 0 | V23: =N23-R23 -> 0 | W23: =O23-S23 -> 0 | Y23: =V23 -> 0 | Z23: =W23 -> 0 | AB23: =O23 -> 29805467 | AD23: 207664.29 | AF23: =AB23-AD23 -> 29597803 | AG23: 637151.43 | AM23: =SUM(AG23:AL23) -> 637151.43 | AN23: =AF23-AM23 -> 28960652
A24: 19 | B24: ASIAN COLLEGE OF SCIENCE AND TECHNOLOGY FDN. INC. | C24: BPI ONLINE | D24: Customer | F24: =+'29'!F24+'30'!F24+'31'!F24 -> 0 | G24: =+'29'!G24+'30'!G24+'31'!G24 -> 0 | H24: =+'29'!H24+'30'!H24+'31'!H24 -> 0 | J24: =+'29'!J24+'30'!J24+'31'!J24 -> 0 | K24: =+'29'!K24+'30'!K24+'31'!K24 -> 0 | L24: =+'29'!L24+'30'!L24+'31'!L24 -> 0 | N24: =+'29'!N24+'30'!N24+'31'!N24 -> 0 | O24: =+'29'!O24+'30'!O24+'31'!O24 -> 0 | P24: =+'29'!P24+'30'!P24+'31'!P24 -> 0 | R24: 0 | S24: 0 | T24: 0 | V24: =N24-R24 -> 0 | W24: =O24-S24 -> 0 | Y24: =V24 -> 0 | Z24: =W24 -> 0 | AB24: =O24 -> 0 | AF24: =AB24-AD24 -> 0 | AM24: =SUM(AG24:AL24) -> 0 | AN24: =AF24-AM24 -> 0
A25: 20 | B25: ASIAN COLLEGE OF TECHNOLOGY (ACT) | D25: Customer | F25: =+'29'!F25+'30'!F25+'31'!F25 -> 0 | G25: =+'29'!G25+'30'!G25+'31'!G25 -> 0 | H25: =+'29'!H25+'30'!H25+'31'!H25 -> 0 | J25: =+'29'!J25+'30'!J25+'31'!J25 -> 0 | K25: =+'29'!K25+'30'!K25+'31'!K25 -> 0 | L25: =+'29'!L25+'30'!L25+'31'!L25 -> 0 | N25: =+'29'!N25+'30'!N25+'31'!N25 -> 0 | O25: =+'29'!O25+'30'!O25+'31'!O25 -> 0 | P25: =+'29'!P25+'30'!P25+'31'!P25 -> 0 | R25: 0 | S25: 0 | T25: 0 | V25: =N25-R25 -> 0 | W25: =O25-S25 -> 0 | Y25: =V25 -> 0 | Z25: =W25 -> 0 | AB25: =O25 -> 0 | AF25: =AB25-AD25 -> 0 | AM25: =SUM(AG25:AL25) -> 0 | AN25: =AF25-AM25 -> 0
A26: 21 | B26: ASIAN INTERNATIONAL SCHOOL OF AERONAUTICS AND TECHNOLOGY (AISAT) CORP. | C26: METROBANK | D26: Customer | F26: =+'29'!F26+'30'!F26+'31'!F26 -> 2 | G26: =+'29'!G26+'30'!G26+'31'!G26 -> 18200 | H26: =+'29'!H26+'30'!H26+'31'!H26 -> 60 | J26: =+'29'!J26+'30'!J26+'31'!J26 -> 0 | K26: =+'29'!K26+'30'!K26+'31'!K26 -> 0 | L26: =+'29'!L26+'30'!L26+'31'!L26 -> 0 | N26: =+'29'!N26+'30'!N26+'31'!N26 -> 2 | O26: =+'29'!O26+'30'!O26+'31'!O26 -> 18200 | P26: =+'29'!P26+'30'!P26+'31'!P26 -> 60 | R26: 2 | S26: 18200 | T26: 0 | V26: =N26-R26 -> 0 | W26: =O26-S26 -> 0 | Y26: =V26 -> 0 | Z26: =W26 -> 0 | AB26: =O26 -> 18200 | AF26: =AB26-AD26 -> 18200 | AM26: =SUM(AG26:AL26) -> 0 | AN26: =AF26-AM26 -> 18200
A27: 22 | B27: ATENEO DE DAVAO UNIVERSITY | C27: PNB | D27: Customer | F27: =+'29'!F27+'30'!F27+'31'!F27 -> 0 | G27: =+'29'!G27+'30'!G27+'31'!G27 -> 0 | H27: =+'29'!H27+'30'!H27+'31'!H27 -> 0 | J27: =+'29'!J27+'30'!J27+'31'!J27 -> 0 | K27: =+'29'!K27+'30'!K27+'31'!K27 -> 0 | L27: =+'29'!L27+'30'!L27+'31'!L27 -> 0 | N27: =+'29'!N27+'30'!N27+'31'!N27 -> 0 | O27: =+'29'!O27+'30'!O27+'31'!O27 -> 0 | P27: =+'29'!P27+'30'!P27+'31'!P27 -> 0 | R27: 0 | S27: 0 | T27: 0 | V27: =N27-R27 -> 0 | W27: =O27-S27 -> 0 | Y27: =V27 -> 0 | Z27: =W27 -> 0 | AB27: =O27 -> 0 | AF27: =AB27-AD27 -> 0 | AM27: =SUM(AG27:AL27) -> 0 | AN27: =AF27-AM27 -> 0
A28: 23 | B28: ATENEO DE ZAMBOANGA UNIVERSITY | C28: METROBANK | D28: Customer | F28: =+'29'!F28+'30'!F28+'31'!F28 -> 0 | G28: =+'29'!G28+'30'!G28+'31'!G28 -> 0 | H28: =+'29'!H28+'30'!H28+'31'!H28 -> 0 | J28: =+'29'!J28+'30'!J28+'31'!J28 -> 0 | K28: =+'29'!K28+'30'!K28+'31'!K28 -> 0 | L28: =+'29'!L28+'30'!L28+'31'!L28 -> 0 | N28: =+'29'!N28+'30'!N28+'31'!N28 -> 0 | O28: =+'29'!O28+'30'!O28+'31'!O28 -> 0 | P28: =+'29'!P28+'30'!P28+'31'!P28 -> 0 | R28: 0 | S28: 0 | T28: 0 | V28: =N28-R28 -> 0 | W28: =O28-S28 -> 0 | Y28: =V28 -> 0 | Z28: =W28 -> 0 | AB28: =O28 -> 0 | AF28: =AB28-AD28 -> 0 | AM28: =SUM(AG28:AL28) -> 0 | AN28: =AF28-AM28 -> 0
A29: 24 | B29: ATLAS CEBU CORN MILL CORP | C29: CHINABANK | D29: Customer | F29: =+'29'!F29+'30'!F29+'31'!F29 -> 11 | G29: =+'29'!G29+'30'!G29+'31'!G29 -> 634315 | H29: =+'29'!H29+'30'!H29+'31'!H29 -> 550 | J29: =+'29'!J29+'30'!J29+'31'!J29 -> 0 | K29: =+'29'!K29+'30'!K29+'31'!K29 -> 0 | L29: =+'29'!L29+'30'!L29+'31'!L29 -> 0 | N29: =+'29'!N29+'30'!N29+'31'!N29 -> 11 | O29: =+'29'!O29+'30'!O29+'31'!O29 -> 634315 | P29: =+'29'!P29+'30'!P29+'31'!P29 -> 550 | R29: 11 | S29: 634315 | T29: 0 | V29: =N29-R29 -> 0 | W29: =O29-S29 -> 0 | Y29: =V29 -> 0 | Z29: =W29 -> 0 | AB29: =O29 -> 634315 | AF29: =AB29-AD29 -> 634315 | AM29: =SUM(AG29:AL29) -> 0 | AN29: =AF29-AM29 -> 634315
A30: 25 | B30: BAKERS BEST MARKETING CORPORATION | C30: BPI | D30: Customer | F30: =+'29'!F30+'30'!F30+'31'!F30 -> 7 | G30: =+'29'!G30+'30'!G30+'31'!G30 -> 48204 | H30: =+'29'!H30+'30'!H30+'31'!H30 -> 210 | J30: =+'29'!J30+'30'!J30+'31'!J30 -> 0 | K30: =+'29'!K30+'30'!K30+'31'!K30 -> 0 | L30: =+'29'!L30+'30'!L30+'31'!L30 -> 0 | N30: =+'29'!N30+'30'!N30+'31'!N30 -> 7 | O30: =+'29'!O30+'30'!O30+'31'!O30 -> 48204 | P30: =+'29'!P30+'30'!P30+'31'!P30 -> 210 | R30: 7 | S30: 48204 | T30: 0 | V30: =N30-R30 -> 0 | W30: =O30-S30 -> 0 | Y30: =V30 -> 0 | Z30: =W30 -> 0 | AB30: =O30 -> 48204 | AF30: =AB30-AD30 -> 48204 | AM30: =SUM(AG30:AL30) -> 0 | AN30: =AF30-AM30 -> 48204
A31: 26 | B31: BALAMBAN ENERZONE | D31: No Billers | F31: =+'29'!F31+'30'!F31+'31'!F31 -> 0 | G31: =+'29'!G31+'30'!G31+'31'!G31 -> 0 | H31: =+'29'!H31+'30'!H31+'31'!H31 -> 0 | J31: =+'29'!J31+'30'!J31+'31'!J31 -> 0 | K31: =+'29'!K31+'30'!K31+'31'!K31 -> 0 | L31: =+'29'!L31+'30'!L31+'31'!L31 -> 0 | N31: =+'29'!N31+'30'!N31+'31'!N31 -> 0 | O31: =+'29'!O31+'30'!O31+'31'!O31 -> 0 | P31: =+'29'!P31+'30'!P31+'31'!P31 -> 0 | R31: 0 | S31: 0 | T31: 0 | V31: =N31-R31 -> 0 | W31: =O31-S31 -> 0 | Y31: =V31 -> 0 | Z31: =W31 -> 0 | AB31: =O31 -> 0 | AF31: =AB31-AD31 -> 0 | AM31: =SUM(AG31:AL31) -> 0 | AN31: =AF31-AM31 -> 0
A32: 27 | B32: BALAMBAN WATER DISTRICT | C32: LANBANK | D32: Customer | F32: =+'29'!F32+'30'!F32+'31'!F32 -> 27 | G32: =+'29'!G32+'30'!G32+'31'!G32 -> 12767.65 | H32: =+'29'!H32+'30'!H32+'31'!H32 -> 270 | J32: =+'29'!J32+'30'!J32+'31'!J32 -> 0 | K32: =+'29'!K32+'30'!K32+'31'!K32 -> 0 | L32: =+'29'!L32+'30'!L32+'31'!L32 -> 0 | N32: =+'29'!N32+'30'!N32+'31'!N32 -> 27 | O32: =+'29'!O32+'30'!O32+'31'!O32 -> 12767.65 | P32: =+'29'!P32+'30'!P32+'31'!P32 -> 270 | R32: 27 | S32: 12767.65 | T32: 0 | V32: =N32-R32 -> 0 | W32: =O32-S32 -> 0 | Y32: =V32 -> 0 | Z32: =W32 -> 0 | AB32: =O32 -> 12767.65 | AF32: =AB32-AD32 -> 12767.65 | AM32: =SUM(AG32:AL32) -> 0 | AN32: =AF32-AM32 -> 12767.65
A33: 28 | B33: BASIC WATER ENTERPRISES INC. | C33: METROBANK | D33: Partner | F33: =+'29'!F33+'30'!F33+'31'!F33 -> 0 | G33: =+'29'!G33+'30'!G33+'31'!G33 -> 0 | H33: =+'29'!H33+'30'!H33+'31'!H33 -> 0 | J33: =+'29'!J33+'30'!J33+'31'!J33 -> 0 | K33: =+'29'!K33+'30'!K33+'31'!K33 -> 0 | L33: =+'29'!L33+'30'!L33+'31'!L33 -> 0 | N33: =+'29'!N33+'30'!N33+'31'!N33 -> 0 | O33: =+'29'!O33+'30'!O33+'31'!O33 -> 0 | P33: =+'29'!P33+'30'!P33+'31'!P33 -> 0 | R33: 0 | S33: 0 | T33: 0 | V33: =N33-R33 -> 0 | W33: =O33-S33 -> 0 | Y33: =V33 -> 0 | Z33: =W33 -> 0 | AB33: =O33 -> 0 | AF33: =AB33-AD33 -> 0 | AM33: =SUM(AG33:AL33) -> 0 | AN33: =AF33-AM33 -> 0
A34: 29 | B34: BATANGAS CATV, INC. - BATANGAS | D34: Customer | F34: =+'29'!F34+'30'!F34+'31'!F34 -> 0 | G34: =+'29'!G34+'30'!G34+'31'!G34 -> 0 | H34: =+'29'!H34+'30'!H34+'31'!H34 -> 0 | J34: =+'29'!J34+'30'!J34+'31'!J34 -> 0 | K34: =+'29'!K34+'30'!K34+'31'!K34 -> 0 | L34: =+'29'!L34+'30'!L34+'31'!L34 -> 0 | N34: =+'29'!N34+'30'!N34+'31'!N34 -> 0 | O34: =+'29'!O34+'30'!O34+'31'!O34 -> 0 | P34: =+'29'!P34+'30'!P34+'31'!P34 -> 0 | R34: 0 | S34: 0 | T34: 0 | V34: =N34-R34 -> 0 | W34: =O34-S34 -> 0 | Y34: =V34 -> 0 | Z34: =W34 -> 0 | AB34: =O34 -> 0 | AF34: =AB34-AD34 -> 0 | AM34: =SUM(AG34:AL34) -> 0 | AN34: =AF34-AM34 -> 0
A35: 30 | B35: BATANGAS CATV, INC. - BAUAN | D35: Customer | F35: =+'29'!F35+'30'!F35+'31'!F35 -> 0 | G35: =+'29'!G35+'30'!G35+'31'!G35 -> 0 | H35: =+'29'!H35+'30'!H35+'31'!H35 -> 0 | J35: =+'29'!J35+'30'!J35+'31'!J35 -> 0 | K35: =+'29'!K35+'30'!K35+'31'!K35 -> 0 | L35: =+'29'!L35+'30'!L35+'31'!L35 -> 0 | N35: =+'29'!N35+'30'!N35+'31'!N35 -> 0 | O35: =+'29'!O35+'30'!O35+'31'!O35 -> 0 | P35: =+'29'!P35+'30'!P35+'31'!P35 -> 0 | R35: 0 | S35: 0 | T35: 0 | V35: =N35-R35 -> 0 | W35: =O35-S35 -> 0 | Y35: =V35 -> 0 | Z35: =W35 -> 0 | AB35: =O35 -> 0 | AF35: =AB35-AD35 -> 0 | AM35: =SUM(AG35:AL35) -> 0 | AN35: =AF35-AM35 -> 0
A36: 31 | B36: BAYAD CENTER - NBI | D36: No Billers | F36: =+'29'!F36+'30'!F36+'31'!F36 -> 0 | G36: =+'29'!G36+'30'!G36+'31'!G36 -> 0 | H36: =+'29'!H36+'30'!H36+'31'!H36 -> 0 | J36: =+'29'!J36+'30'!J36+'31'!J36 -> 0 | K36: =+'29'!K36+'30'!K36+'31'!K36 -> 0 | L36: =+'29'!L36+'30'!L36+'31'!L36 -> 0 | N36: =+'29'!N36+'30'!N36+'31'!N36 -> 0 | O36: =+'29'!O36+'30'!O36+'31'!O36 -> 0 | P36: =+'29'!P36+'30'!P36+'31'!P36 -> 0 | R36: 0 | S36: 0 | T36: 0 | V36: =N36-R36 -> 0 | W36: =O36-S36 -> 0 | Y36: =V36 -> 0 | Z36: =W36 -> 0 | AB36: =O36 -> 0 | AF36: =AB36-AD36 -> 0 | AM36: =SUM(AG36:AL36) -> 0 | AN36: =AF36-AM36 -> 0
A37: 32 | B37: BAYAN TELECOMMUNICATIONS INC | C37: BDO | D37: CusPart | F37: =+'29'!F37+'30'!F37+'31'!F37 -> 0 | G37: =+'29'!G37+'30'!G37+'31'!G37 -> 0 | H37: =+'29'!H37+'30'!H37+'31'!H37 -> 0 | J37: =+'29'!J37+'30'!J37+'31'!J37 -> 0 | K37: =+'29'!K37+'30'!K37+'31'!K37 -> 0 | L37: =+'29'!L37+'30'!L37+'31'!L37 -> 0 | N37: =+'29'!N37+'30'!N37+'31'!N37 -> 0 | O37: =+'29'!O37+'30'!O37+'31'!O37 -> 0 | P37: =+'29'!P37+'30'!P37+'31'!P37 -> 0 | R37: 0 | S37: 0 | T37: 0 | V37: =N37-R37 -> 0 | W37: =O37-S37 -> 0 | Y37: =V37 -> 0 | Z37: =W37 -> 0 | AB37: =O37 -> 0 | AF37: =AB37-AD37 -> 0 | AM37: =SUM(AG37:AL37) -> 0 | AN37: =AF37-AM37 -> 0
A38: 33 | B38: BBBROTHERS DV GEN. MDSE INC | C38: BDO ONLINE | D38: Customer | F38: =+'29'!F38+'30'!F38+'31'!F38 -> 5 | G38: =+'29'!G38+'30'!G38+'31'!G38 -> 58165 | H38: =+'29'!H38+'30'!H38+'31'!H38 -> 150 | J38: =+'29'!J38+'30'!J38+'31'!J38 -> 0 | K38: =+'29'!K38+'30'!K38+'31'!K38 -> 0 | L38: =+'29'!L38+'30'!L38+'31'!L38 -> 0 | N38: =+'29'!N38+'30'!N38+'31'!N38 -> 5 | O38: =+'29'!O38+'30'!O38+'31'!O38 -> 58165 | P38: =+'29'!P38+'30'!P38+'31'!P38 -> 150 | R38: 5 | S38: 58165 | T38: 0 | V38: =N38-R38 -> 0 | W38: =O38-S38 -> 0 | Y38: =V38 -> 0 | Z38: =W38 -> 0 | AB38: =O38 -> 58165 | AF38: =AB38-AD38 -> 58165 | AM38: =SUM(AG38:AL38) -> 0 | AN38: =AF38-AM38 -> 58165
A39: 34 | B39: BBBROTHERS LAGUNA INC 001 | C39: BDO ONLINE | D39: Customer | F39: =+'29'!F39+'30'!F39+'31'!F39 -> 0 | G39: =+'29'!G39+'30'!G39+'31'!G39 -> 0 | H39: =+'29'!H39+'30'!H39+'31'!H39 -> 0 | J39: =+'29'!J39+'30'!J39+'31'!J39 -> 0 | K39: =+'29'!K39+'30'!K39+'31'!K39 -> 0 | L39: =+'29'!L39+'30'!L39+'31'!L39 -> 0 | N39: =+'29'!N39+'30'!N39+'31'!N39 -> 0 | O39: =+'29'!O39+'30'!O39+'31'!O39 -> 0 | P39: =+'29'!P39+'30'!P39+'31'!P39 -> 0 | R39: 0 | S39: 0 | T39: 0 | V39: =N39-R39 -> 0 | W39: =O39-S39 -> 0 | Y39: =V39 -> 0 | Z39: =W39 -> 0 | AB39: =O39 -> 0 | AF39: =AB39-AD39 -> 0 | AM39: =SUM(AG39:AL39) -> 0 | AN39: =AF39-AM39 -> 0
A40: 35 | B40: BBBROTHERS LAGUNA INC 002 | C40: BDO ONLINE | D40: Customer | F40: =+'29'!F40+'30'!F40+'31'!F40 -> 0 | G40: =+'29'!G40+'30'!G40+'31'!G40 -> 0 | H40: =+'29'!H40+'30'!H40+'31'!H40 -> 0 | J40: =+'29'!J40+'30'!J40+'31'!J40 -> 0 | K40: =+'29'!K40+'30'!K40+'31'!K40 -> 0 | L40: =+'29'!L40+'30'!L40+'31'!L40 -> 0 | N40: =+'29'!N40+'30'!N40+'31'!N40 -> 0 | O40: =+'29'!O40+'30'!O40+'31'!O40 -> 0 | P40: =+'29'!P40+'30'!P40+'31'!P40 -> 0 | R40: 0 | S40: 0 | T40: 0 | V40: =N40-R40 -> 0 | W40: =O40-S40 -> 0 | Y40: =V40 -> 0 | Z40: =W40 -> 0 | AB40: =O40 -> 0 | AF40: =AB40-AD40 -> 0 | AM40: =SUM(AG40:AL40) -> 0 | AN40: =AF40-AM40 -> 0
...

Sheet PAID SC
A1: COLLECTION MONITORING
A2: As of August 31, 2025
B4: AUGUST 2025
B5: AMOUNT | C5: PAYMENT PERIOD
A6: SPICA DISTRIBUTION | B6: 0
A7: PLDT | B7: 0
A8: NORECO | B8: 0
A9: HAPPY WELL | B9: 0
A10: KALUNASAN | B10: 0
A11: RELEVANTTECH 5-DSP | B11: 25638.839 | C11: JULY 2025
A12: RELEVANTTECH 5-PROJECT | B12: 4964.7321 | C12: JULY 2025
A13: RELEVANTTECH 5-SUB DEALER | B13: 2254.0179 | C13: JULY 2025
A14: RELEVANTTECH 6-DSP | B14: 37468.75 | C14: JULY 2025
A15: RELEVANTTECH 6-PROJECT | B15: 5112.0536 | C15: JULY 2025
A16: RELEVANTTECH 6-SUB DEALER | B16: 3221.4286 | C16: JULY 2025
A17: PRIMUS VENTURES | B17: 0
A18: MANILA WATER VENTURE | B18: 474.48 | C18: AUGUST 2024 & FEBRUARY 2025
A19: PAL | B19: 4611.16 | C19: APRIL-JUNE 2025
A20: RYKOM | B20: 0
A21: WATER PHILS | B21: 2003.57 | C21: MAY-JUNE 2025
A22: CITY SAVINGS | B22: 0
A23: CEBU GEMS | B23: 0
A24: ASIALINK | B24: 207664.29 | C24: JUNE 2025
A25: FINASWIDE | B25: 0
A26: SUBIC ENERZONE | B26: 0
A27: DAVAO LIGHT | B27: 0
A28: VECO | B28: 0
A29: COTABATO LIGHT | B29: 0
A30: ANECO | B30: 1866.0714 | C30: JUNE 2025
A31: ANECO - COLLECTION | B31: 0
A32: GENTRADE | B32: 699305.36 | C32: JUNE-JULY 2025
A33: POWERCYCLE | B33: 156042.86 | C33: JUNE-JULY 2025
A34: UNISTAR-FINANCE | B34: 70596.43 | C34: JUNE-JULY 2025
A35: UNISTAR-CUSTOMER | B35: 486.16 | C35: JUNE-JULY 2025
A36: MILLENIUM | B36: 61708.036 | C36: JULY 2025
A37: MAKATI-CUSTOMER | B37: 810.27 | C37: MAY-JUNE 2025
A38: MAKATI-FINANCE | B38: 21852.68 | C38: MAY-JUNE 2025
A39: MICROVENTURES | B39: 0
A40: DRAGONPAY | B40: 1943275.7 | C40: June 16-July 31, 2025
A41: CIS BAYAD CENTER | B41: 0
...

Sheet UNPAID SF
A1: BILLS PAYMENT SERVICE CHARGE RECEIVABLES
A2: As of August 31, 2025
D3: 45870 | E3: 45839 | F3: 45809 | G3: 45778 | H3: 45748 | I3: March 2025 & Previous
F4: AGING
A5: PARTNER | B5: AMOUNT | C5: REMARKS | D5: CURRENT | E5: 1-30 DAYS | F5: 31-60 DAYS | G5: 61-90 DAYS | H5: 90 DAYS | I5: OVER 90 DAYS
A6: SPICA | B6: =SUM(D6:I6) -> 10017.857 | D6: 2916.9643 | E6: 3908.9286 | F6: 3191.9643 | G6: 0 | H6: 0 | I6: 0
A7: NORECO | B7: =SUM(D7:I7) -> 110687.5 | D7: 13897.321 | E7: 14241.071 | F7: 13062.5 | G7: 12767.857 | H7: 12227.679 | I7: =29857.1428571429+14633.9285714286 -> 44491.071
A8: HAPPY WELL | B8: =SUM(D8:I8) -> 1178.5714 | D8: 495 | E8: 361.42857 | F8: 322.14286 | G8: 0 | H8: 0 | I8: 0
A9: KALUNASAN | B9: =SUM(D9:I9) -> 0 | D9: 0 | E9: 0 | F9: 0 | G9: 0 | H9: 0 | I9: 0
A10: RELEVANTTECH 5-DSP | B10: =SUM(D10:I10) -> 19917.857 | D10: 19917.857 | E10: 0 | F10: 0 | G10: 0 | H10: 0 | I10: 0
A11: RELEVANTTECH 5-PROJECT | B11: =SUM(D11:I11) -> 3378.5714 | D11: 3378.5714 | E11: 0 | F11: 0 | G11: 0 | H11: 0 | I11: 0
A12: RELEVANTTECH 5-SUB DEALER | B12: =SUM(D12:I12) -> 1738.3929 | D12: 1738.3929 | E12: 0 | F12: 0 | G12: 0 | H12: 0 | I12: 0
A13: RELEVANTTECH 6-DSP | B13: =SUM(D13:I13) -> 30657.589 | D13: 30657.589 | E13: 0 | F13: 0 | G13: 0 | H13: 0 | I13: 0
A14: RELEVANTTECH 6-PROJECT | B14: =SUM(D14:I14) -> 4144.6429 | D14: 4144.6429 | E14: 0 | F14: 0 | G14: 0 | H14: 0 | I14: 0
A15: RELEVANTTECH 6-SUB DEALER | B15: =SUM(D15:I15) -> 4566.9643 | D15: 4566.9643 | E15: 0 | F15: 0 | G15: 0 | H15: 0 | I15: 0
A16: PRIMUS VENTURES | B16: =SUM(D16:I16) -> 39737.5 | D16: 29336.607 | E16: 3211.6071 | F16: 5136.6071 | H16: 1021.4286 | I16: 1031.25
A17: MANILA WATER VENTURE | B17: =SUM(D17:I17) -> 137.5 | D17: 0 | E17: 0 | F17: 0 | G17: 0 | H17: 0 | I17: 137.5
A18: OBANDO WATER | B18: =SUM(D18:I18) -> 55 | D18: 0 | E18: 0 | F18: 0 | G18: 0 | H18: 0 | I18: 55
A19: LAGUNA WATER CORP | B19: =SUM(D19:I19) -> 2667.5 | D19: 2667.5 | E19: 0 | F19: 0 | G19: 0 | H19: 0 | I19: 0
A20: PAL | B20: =SUM(D20:I20) -> 2003.5714 | D20: 987.05357 | E20: 1016.5179 | F20: 0 | G20: 0 | H20: 0 | I20: 0
A21: RYKOM | B21: =SUM(D21:I21) -> 10675 | D21: 4950 | E21: 5725 | F21: 0 | G21: 0 | H21: 0 | I21: 0
A22: WATER PHILS | B22: =SUM(D22:I22) -> 2003.5714 | D22: 1031.25 | E22: 972.32143 | F22: 0 | G22: 0 | H22: 0 | I22: 0
A23: CITY SAVINGS | B23: =SUM(D23:I23) -> 2645843.8 | D23: 1313223.2 | E23: 1332620.5 | F23: 0 | G23: 0 | H23: 0 | I23: 0
A24: CEBU GEMS | B24: =SUM(D24:I24) -> 98.214286 | D24: 0 | E24: 0 | F24: 0 | G24: 0 | H24: 0 | I24: 98.214286
A25: ASIALINK | B25: =SUM(D25:I25) -> 637151.43 | D25: 208120 | E25: 211922.86 | F25: 0 | G25: 217108.57 | H25: 0 | I25: 0
A26: FINASWIDE | B26: =SUM(D26:I26) -> 1147.1429 | D26: 110 | E26: 235.71429 | F26: 251.42857 | G26: 0 | H26: 330 | I26: 220
A27: SUBIC ENERZONE | B27: =SUM(D27:I27) -> 68.6 | D27: 14.7 | E27: 14.7 | F27: 19.6 | G27: 19.6 | H27: 0 | I27: 0
A28: DAVAO LIGHT | B28: =SUM(D28:I28) -> 103974.55 | D28: 33770.982 | E28: 35853.125 | F28: 34350.446 | G28: 0 | H28: 0 | I28: 0
... A44: RAFI MICROFINANCE | B44: =SUM(D44:I44) -> 182953.57 | D44: 182953.57 | E44: 0 | F44: 0 | G44: 0 | H44: 0 | I44: 0
A45: RCBC- AMWSLAI | B45: =SUM(D45:I45) -> 358.48214 | D45: 358.48214 | E45: 0 | G45: 0 | H45: 0 | I45: 0
A46: RCBC-BUFFALO FARM | B46: =SUM(D46:I46) -> 3977.6786 | D46: 3977.6786 | E46: 0 | F46: 0 | G46: 0 | H46: 0 | I46: 0
A47: RCBC-BUFFALO IND 1 | B47: =SUM(D47:I47) -> 6806.25 | D47: 6806.25 | E47: 0 | F47: 0 | G47: 0 | H47: 0 | I47: 0
A48: RCBC-BUFFALO IND 2 | B48: =SUM(D48:I48) -> 58.928571 | D48: 58.928571 | E48: 0 | F48: 0 | G48: 0 | H48: 0 | I48: 0
A49: RCBC-CITIBANK | B49: =SUM(D49:I49) -> 68.75 | D49: 0 | E49: 0 | F49: 0 | G49: 0 | H49: 49.107143 | I49: 19.642857
A50: RCBC-CEBU SEA CHARTERERS | B50: =SUM(D50:I50) -> 3683.0343 | D50: 3653.57 | E50: 29.464286 | F50: 0 | G50: 0 | H50: 0 | I50: 0
A51: RCBC-CONSUMER LOANS | B51: =SUM(D51:I51) -> 1198.2143 | D51: 1198.2143 | E51: 0 | F51: 0 | G51: 0 | H51: 0 | I51: 0
A52: RCBC-COCOMART | B52: =SUM(D52:I52) -> 21891.964 | D52: 21891.964 | E52: 0 | F52: 0 | G52: 0 | H52: 0 | I52: 0
A53: RCBC-DWIGHT STEEL | B53: =SUM(D53:I53) -> 0 | D53: 0 | E53: 0 | F53: 0 | G53: 0 | H53: 0 | I53: 0
A54: RCBC-EASTERN VISAYAS | B54: =SUM(D54:I54) -> 142.41071 | D54: 142.41071 | E54: 0 | F54: 0 | G54: 0 | H54: 0 | I54: 0
A55: RCBC-GLOBAL | B55: =SUM(D55:I55) -> 4596.4286 | D55: 4596.4286 | E55: 0 | F55: 0 | G55: 0 | H55: 0 | I55: 0
...

Sheet BPW UNDEDUCTED
A1: As of March 31, 2025
A2: As of April 30, 2025
A3: DATE OF TRANSACTION | B3: REFERENCE | C3: ACCOUNT NAME | D3: ACCOUNT NO. | E3: BP PARTNER | F3: TRXN | G3: AMOUNT | H3: AMOUNT FOR REFUND | J3: TOTAL PER BP | K3: REMARKS
A4: 43968.022 | B4: BPW00111749884005 | C4: ROEL SILVANO SAYSON | D4: 20040000384075 | E4: DRAGON PAY CORPORATION | F4: 1 | G4: 650 | H4: 650 | I4: 20 | K4: not allowed for reversal, successfully posted to their partner
A5: 43970.533 | B5: BPW00111914906605 | C5: TERESA CENIZA PALCIS | D5: 17040000015156 | E5: DRAGON PAY CORPORATION | F5: 1 | G5: 855 | H5: 855 | I5: 20 | K5: not allowed for reversal, successfully posted to their partner
A6: 43894.004 | B6: BPW00110447760203 | C6: KATHLEEN MAY RAMIREZ SALANO | D6: 19110000318514 | E6: DRAGON PAY CORPORATION | F6: 1 | G6: 1794 | H6: 1794 | I6: 20 | J6: =SUM(H4:H6) -> 3299 | K6: not allowed for reversal, successfully posted to their partner
A7: 2020-02-14 15:39:41 PM | B7: BPW00111496572802 | C7: MERASOL CAFE BAGALANON | D7: 18030000036261 | E7: GI PHILIPPINES CORP. | F7: 1 | G7: 5000 | H7: 5000 | K7: PARTNER NOT ALLOWED FOR MANUAL ADJUSTMENT
A8: 43970.414 | B8: BPW00111983957805 | C8: DANNIELYN GRACE LUNA PEREZ | D8: 18120000131450 | E8: GI PHILIPPINES CORP. | F8: 1 | G8: 5000 | H8: 5000 | I8: 50 | K8: PARTNER NOT ALLOWED FOR MANUAL ADJUSTMENT
A9: 2020-06-01 11:39:02 AM | B9: BPW00110155044906 | C9: PEREZ, DANNIELYN GRACE LUNA | D9: 18120000131450 | E9: GI PHILIPPINES CORP. | F9: 1 | G9: 10000 | H9: 10000 | I9: 50 | J9: =SUM(H7:H9) -> 20000 | K9: PARTNER NOT ALLOWED FOR MANUAL ADJUSTMENT
A10: 43972.333 | B10: BPW00112142559405 | C10: ADRIAN MOLIDOR PONTIPEDRA | D10: 17010000006196 | E10: LAZADA PH | F10: 1 | G10: 500 | H10: 500 | I10: 0 | J10: =SUM(H10) -> 500 | K10: not allowed for reversal, successfully posted to their partner
A11: 2020-06-26 21:02:18 PM | B11: BPW00112695252706 | C11: WAMILDA, EYEIN LYNN MERISAAR | D11: 19110000326037 | E11: SKYPAY API | F11: 1 | G11: 800 | H11: 800 | I11: 20 | J11: =SUM(H11) -> 800 | K11: Lending refused to cancel due to customer have reloan again
A13: SUMMARY:
A14: DRAGON PAY CORPORATION | B14: 3299
A15: BIYAHEKO.COM | B15: 20000
A16: LAZADA PH | B16: 500
A17: SKYPAY API | B17: 800
B18: =SUM(B14:B17) -> 24599

Sheet BPX UNDEDUCTED
A1: As of August 31, 2025
A2: BPX UNDEDUCTED
A4: DATE | B4: REFERENCE | C4: ACCOUNT NAME | D4: BP PARTNER | E4: AMOUNT | F4: TOTAL AMOUNT PER BP | G4: REASON | H4: REMARKS
A5: 2021-05-01 09:50:44 | B5: BPX00110162242105 | C5: LEVINIA COLEGA SEGUIN | D5: CITY SAVINGS BANK | E5: 12500 | F5: =E5 -> 12500 | G5: unposted and undeductec on agent wallet balance | H5: emailed 05/08/2021
A6: 2021-06-02 15:29:37 | B6: BPX00110220819606 | C6: NCDIMARUCUT2851 | D6: ILECO 3 | E6: 495.66 | G6: unposted and undeducted on agent wallet balance | H6: waiting for partner's approval
A7: 2021-06-02 16:00:14 | B7: BPX00110271350306 | C7: NCDIMARUCUT2851 | D7: ILECO 3 | E7: 233.72 | F7: =E7+E6 -> 729.38 | G7: unposted and undeducted on agent wallet balance | H7: waiting for partner's approval
A8: 2021-02-26 10:45:12 AM | B8: BPX00112625562102 | C8: danertagadan38 | D8: MY SUPER PAY | E8: 4560 | F8: =E8 -> 4560 | G8: unposted and undeducted on our monthly report (FOR ADJUSTMENT-NO TRXN OF SUPERPAY YET) | H8: still no transaction yet; for adjustment
A9: 2021-05-03 11:43:23 | B9: BPX00110369639605 | C9: ARGY GUMANGAN CAASI | D9: PANELCO 1 | E9: 34 | F9: =E9 -> 34 | G9: unposted and undeductec on agent wallet balance | H9: emailed partner for approval, last ff. 4/20/22
A10: 2020-10-20 11:03:35 AM | B10: BPX00112068500310 | C10: EPHRAINE NICOLE GO REDONA | D10: SKYPAY | E10: 8050 | G10: Lending not approved due to customer account already settled on their end, can't be adjust or cancel | H10: not allowed for reversal
A11: 2020-10-20 10:57:43 AM | B11: BPX00112073845610 | C11: EPHRAINE NICOLE GO REDONA | D11: SKYPAY | E11: 8050 | G11: Lending not approved due to customer account already settled on their end, can't be adjust or cancel | H11: not allowed for reversal
A12: 2020-10-21 10:46:04 AM | B12: BPX00112160978010 | C12: MARY GRACE LUMBANG LAREZA | D12: SKYPAY | E12: 3500 | G12: Lending not approved | H12: Lending not approved
A13: 2020-10-20 01:13:12 PM | B13: BPX00112020551910 | C13: RAISA HARMONY CHOMAPOY LALO | D13: SKYPAY | E13: 2125 | G13: Lending not approved | H13: Lending not approved
A14: 2021-01-03 10:28:03 AM | B14: BPX00110369653401 | C14: ASUGAO, BENJIE PEPITO | D14: SKYPAY | E14: 2200 | G14: posted on your web report but unposted and undeducted to our transaction history report | H14: not allowed for reversal
A15: 2021-01-11 09:55:00 AM | B15: BPX00111136906601 | C15: MENIANO, LORELIE REYES | D15: SKYPAY | E15: 2500 | G15: posted on your web report but unposted and undeducted to our transaction history report | H15: not allowed for reversal
A16: 2019-12-28 03:34:30 PM | B16: BPX00112831443712 | C16: ERIC SAWATI CATTE | D16: SKYPAY API | E16: 2000 | H16: Lending not approved
A17: 2019-12-28 03:36:31 PM | B17: BPX00112841790612 | C17: ERIC SAWATI CATTE | D17: SKYPAY API | E17: 2000 | H17: Lending not approved
A18: 2020-01-08 04:14:23 PM | B18: BPX00110812123701 | C18: CATHERINE DEMAOSA ENDOMA | D18: SKYPAY API | E18: 3000 | G18: With receipt but reference not match | H18: lending not approved
A19: 2020-01-07 02:07:25 PM | B19: BPX00110728689001 | C19: ERIC SAWATI CATTE | D19: SKYPAY API | E19: 280 | G19: With receipt but reference not match | H19: Lending not approved due to customer have repeat loan
A20: 2020-01-07 10:58:53 AM | B20: BPX00110731901801 | C20: ERIC SAWATI CATTE | D20: SKYPAY API | E20: 7980 | G20: With receipt but reference not match | H20: NOT APPROVED TO CANCEL due to customer account already settled in lending’s end
A21: 2020-01-07 04:47:10 PM | B21: BPX00110736885101 | C21: JOCELYN CIRUELA SAKAY | D21: SKYPAY API | E21: 2000 | H21: Lending not approved
A22: 2020-01-07 04:49:08 PM | B22: BPX00110767047801 | C22: JOCELYN CIRUELA SAKAY | D22: SKYPAY API | E22: 2000 | H22: Lending not approved
A23: 2020-01-08 01:28:39 PM | B23: BPX00110866032201 | C23: EILYN ABROGENA DIZON | D23: SKYPAY API | E23: 3570 | H23: Lending not approved
A24: 2020-01-07 06:13:42 PM | B24: BPX00110756498901 | C24: FRANCISCO JR DILIM AGBAYANI | D24: SKYPAY API | E24: 1650 | G24: As per Agent no Transaction Found | H24: Lending not approved due to customer have repeat loan
